============================= test session starts =============================
platform win32 -- Python 3.7.0, pytest-6.2.4, py-1.11.0, pluggy-0.13.1 -- e:\dev\s_10_project\venv\scripts\python.exe
django: settings: api_yamdb.settings (from ini)
rootdir: E:\Dev\s_10_project\api_yamdb, configfile: pytest.ini, testpaths: tests/
plugins: django-4.4.0, pythonpath-0.7.3
collecting ... collected 53 items

tests/test_00_user_registration.py::Test00UserRegistration::test_00_nodata_signup PASSED [  1%]
tests/test_00_user_registration.py::Test00UserRegistration::test_00_invalid_data_signup PASSED [  3%]
tests/test_00_user_registration.py::Test00UserRegistration::test_00_valid_data_user_signup PASSED [  5%]
tests/test_00_user_registration.py::Test00UserRegistration::test_00_valid_data_admin_create_user FAILED [  7%]
tests/test_00_user_registration.py::Test00UserRegistration::test_00_obtain_jwt_token_invalid_data PASSED [  9%]
tests/test_00_user_registration.py::Test00UserRegistration::test_00_registration_me_username_restricted PASSED [ 11%]
tests/test_00_user_registration.py::Test00UserRegistration::test_00_registration_same_email_restricted FAILED [ 13%]
tests/test_01_users.py::Test01UserAPI::test_01_users_not_authenticated FAILED [ 15%]
tests/test_01_users.py::Test01UserAPI::test_02_users_username_not_authenticated FAILED [ 16%]
tests/test_01_users.py::Test01UserAPI::test_03_users_me_not_authenticated FAILED [ 18%]
tests/test_01_users.py::Test01UserAPI::test_04_users_get_admin FAILED    [ 20%]
tests/test_01_users.py::Test01UserAPI::test_04_02_users_get_search FAILED [ 22%]
tests/test_01_users.py::Test01UserAPI::test_04_01_users_get_admin_only PASSED [ 24%]
tests/test_01_users.py::Test01UserAPI::test_05_01_users_post_admin FAILED [ 26%]
tests/test_01_users.py::Test01UserAPI::test_05_02_users_post_user_superuser PASSED [ 28%]
tests/test_01_users.py::Test01UserAPI::test_06_users_username_get_admin FAILED [ 30%]
tests/test_01_users.py::Test01UserAPI::test_06_users_username_get_not_admin FAILED [ 32%]
tests/test_01_users.py::Test01UserAPI::test_07_01_users_username_patch_admin FAILED [ 33%]
tests/test_01_users.py::Test01UserAPI::test_07_02_users_username_patch_moderator FAILED [ 35%]
tests/test_01_users.py::Test01UserAPI::test_07_03_users_username_patch_user FAILED [ 37%]
tests/test_01_users.py::Test01UserAPI::test_07_05_users_username_put_user_restricted FAILED [ 39%]
tests/test_01_users.py::Test01UserAPI::test_08_01_users_username_delete_admin FAILED [ 41%]
tests/test_01_users.py::Test01UserAPI::test_08_02_users_username_delete_moderator FAILED [ 43%]
tests/test_01_users.py::Test01UserAPI::test_08_03_users_username_delete_user FAILED [ 45%]
tests/test_01_users.py::Test01UserAPI::test_08_04_users_username_delete_superuser FAILED [ 47%]
tests/test_01_users.py::Test01UserAPI::test_09_users_check_permissions FAILED [ 49%]
tests/test_01_users.py::Test01UserAPI::test_10_users_me_get_admin FAILED [ 50%]
tests/test_01_users.py::Test01UserAPI::test_11_01_users_me_patch_admin FAILED [ 52%]
tests/test_01_users.py::Test01UserAPI::test_11_02_users_me_patch_user FAILED [ 54%]
tests/test_02_category.py::Test02CategoryAPI::test_01_category_not_auth PASSED [ 56%]
tests/test_02_category.py::Test02CategoryAPI::test_02_category_admin PASSED [ 58%]
tests/test_02_category.py::Test02CategoryAPI::test_03_category_delete_admin FAILED [ 60%]
tests/test_02_category.py::Test02CategoryAPI::test_04_category_check_permission_admin FAILED [ 62%]
tests/test_02_category.py::Test02CategoryAPI::test_05_category_create_user FAILED [ 64%]
tests/test_02_category.py::Test02CategoryAPI::test_06_category_create_moderator FAILED [ 66%]
tests/test_03_genre.py::Test03GenreAPI::test_01_genre_not_auth PASSED    [ 67%]
tests/test_03_genre.py::Test03GenreAPI::test_02_genre PASSED             [ 69%]
tests/test_03_genre.py::Test03GenreAPI::test_03_genres_delete FAILED     [ 71%]
tests/test_03_genre.py::Test03GenreAPI::test_04_genres_check_permission FAILED [ 73%]
tests/test_03_genre.py::Test03GenreAPI::test_05_genre_create_user FAILED [ 75%]
tests/test_03_genre.py::Test03GenreAPI::test_06_genre_create_moderator FAILED [ 77%]
tests/test_04_title.py::Test04TitleAPI::test_01_title_not_auth PASSED    [ 79%]
tests/test_04_title.py::Test04TitleAPI::test_02_title_admin FAILED       [ 81%]
tests/test_04_title.py::Test04TitleAPI::test_03_titles_detail FAILED     [ 83%]
tests/test_04_title.py::Test04TitleAPI::test_04_titles_check_permission FAILED [ 84%]
tests/test_05_review.py::Test05ReviewAPI::test_01_review_not_auth FAILED [ 86%]
tests/test_05_review.py::Test05ReviewAPI::test_02_review_admin FAILED    [ 88%]
tests/test_05_review.py::Test05ReviewAPI::test_03_review_detail FAILED   [ 90%]
tests/test_05_review.py::Test05ReviewAPI::test_04_reviews_check_permission FAILED [ 92%]
tests/test_06_comment.py::Test06CommentAPI::test_01_comment_not_auth FAILED [ 94%]
tests/test_06_comment.py::Test06CommentAPI::test_02_comment FAILED       [ 96%]
tests/test_06_comment.py::Test06CommentAPI::test_03_review_detail FAILED [ 98%]
tests/test_06_comment.py::Test06CommentAPI::test_04_comment_check_permission FAILED [100%]

================================== FAILURES ===================================
_________ Test00UserRegistration.test_00_valid_data_admin_create_user _________

self = <tests.test_00_user_registration.Test00UserRegistration object at 0x05ADA3B0>
admin_client = <rest_framework.test.APIClient object at 0x05D35F70>

    @pytest.mark.django_db(transaction=True)
    def test_00_valid_data_admin_create_user(self, admin_client):
    
        valid_email = 'valid@yamdb.fake'
        valid_username = 'valid_username'
        outbox_before_count = len(mail.outbox)
    
        valid_data = {
            'email': valid_email,
            'username': valid_username
        }
        request_type = 'POST'
        response = admin_client.post(self.url_admin_create_user, data=valid_data)
        outbox_after = mail.outbox
    
        assert response.status_code != 404, (
            f'—траница `{self.url_admin_create_user}` не найдена, проверьте этот адрес в *urls.py*'
        )
    
        code = 201
>       assert response.status_code == code, (
            f'ѕроверьте, что при {request_type} запросе `{self.url_admin_create_user}` с валидными данными '
            f'от имени администратора, создаетс€ пользователь и возвращаетс€ статус {code}'
        )
E       AssertionError: ѕроверьте, что при POST запросе `/api/v1/users/` с валидными данными от имени администратора, создаетс€ пользователь и возвращаетс€ статус 201
E       assert 403 == 201
E         +403
E         -201

tests\test_00_user_registration.py:142: AssertionError
------------------------------ Captured log call ------------------------------
WARNING  django.request:log.py:228 Forbidden: /api/v1/users/
______ Test00UserRegistration.test_00_registration_same_email_restricted ______

self = <django.db.backends.utils.CursorWrapper object at 0x05EBF710>
sql = 'INSERT INTO "users_user" ("password", "last_login", "is_superuser", "first_name", "last_name", "is_staff", "is_active...", "bio", "role", "is_moderator", "confirmation_code") VALUES (%s, %s, %s, %s, %s, %s, %s, %s, %s, %s, %s, %s, %s, %s)'
params = ['pbkdf2_sha256$150000$YWvCxaVnbjvf$rq89ZoJ6nOdiyf9zC1lHChpYf7JAkoF1WbOHivZgrYk=', None, False, '', '', False, ...]
ignored_wrapper_args = (False, {'connection': <django.db.backends.sqlite3.base.DatabaseWrapper object at 0x04B95750>, 'cursor': <django.db.backends.utils.CursorWrapper object at 0x05EBF710>})

    def _execute(self, sql, params, *ignored_wrapper_args):
        self.db.validate_no_broken_transaction()
        with self.db.wrap_database_errors:
            if params is None:
                return self.cursor.execute(sql)
            else:
>               return self.cursor.execute(sql, params)

..\venv\lib\site-packages\django\db\backends\utils.py:84: 
_ _ _ _ _ _ _ _ _ _ _ _ _ _ _ _ _ _ _ _ _ _ _ _ _ _ _ _ _ _ _ _ _ _ _ _ _ _ _ _

self = <django.db.backends.sqlite3.base.SQLiteCursorWrapper object at 0x05C6C088>
query = 'INSERT INTO "users_user" ("password", "last_login", "is_superuser", "first_name", "last_name", "is_staff", "is_active...rname", "email", "bio", "role", "is_moderator", "confirmation_code") VALUES (?, ?, ?, ?, ?, ?, ?, ?, ?, ?, ?, ?, ?, ?)'
params = ['pbkdf2_sha256$150000$YWvCxaVnbjvf$rq89ZoJ6nOdiyf9zC1lHChpYf7JAkoF1WbOHivZgrYk=', None, False, '', '', False, ...]

    def execute(self, query, params=None):
        if params is None:
            return Database.Cursor.execute(self, query)
        query = self.convert_query(query)
>       return Database.Cursor.execute(self, query, params)
E       sqlite3.IntegrityError: UNIQUE constraint failed: users_user.email

..\venv\lib\site-packages\django\db\backends\sqlite3\base.py:383: IntegrityError

The above exception was the direct cause of the following exception:

self = <tests.test_00_user_registration.Test00UserRegistration object at 0x05E59E90>
client = <django.test.client.Client object at 0x05EC4490>

    @pytest.mark.django_db(transaction=True)
    def test_00_registration_same_email_restricted(self, client):
        valid_email_1 = 'test_duplicate_1@yamdb.fake'
        valid_email_2 = 'test_duplicate_2@yamdb.fake'
        valid_username_1 = 'valid_username_1'
        valid_username_2 = 'valid_username_2'
        request_type = 'POST'
    
        valid_data = {
            'email': valid_email_1,
            'username': valid_username_1
        }
        response = client.post(self.url_signup, data=valid_data)
        code = 200
        assert response.status_code == code, (
            f'ѕроверьте, что при {request_type} запросе `{self.url_signup}` '
            f'можно создать пользовател€ с валидными данными и возвращаетс€ статус {code}'
        )
    
        duplicate_email_data = {
            'email': valid_email_1,
            'username': valid_username_2
        }
>       response = client.post(self.url_signup, data=duplicate_email_data)

tests\test_00_user_registration.py:267: 
_ _ _ _ _ _ _ _ _ _ _ _ _ _ _ _ _ _ _ _ _ _ _ _ _ _ _ _ _ _ _ _ _ _ _ _ _ _ _ _
..\venv\lib\site-packages\django\test\client.py:543: in post
    response = super().post(path, data=data, content_type=content_type, secure=secure, **extra)
..\venv\lib\site-packages\django\test\client.py:357: in post
    secure=secure, **extra)
..\venv\lib\site-packages\django\test\client.py:422: in generic
    return self.request(**r)
..\venv\lib\site-packages\django\test\client.py:503: in request
    raise exc_value
..\venv\lib\site-packages\django\core\handlers\exception.py:34: in inner
    response = get_response(request)
..\venv\lib\site-packages\django\core\handlers\base.py:115: in _get_response
    response = self.process_exception_by_middleware(e, request)
..\venv\lib\site-packages\django\core\handlers\base.py:113: in _get_response
    response = wrapped_callback(request, *callback_args, **callback_kwargs)
..\venv\lib\site-packages\django\views\decorators\csrf.py:54: in wrapped_view
    return view_func(*args, **kwargs)
..\venv\lib\site-packages\django\views\generic\base.py:71: in view
    return self.dispatch(request, *args, **kwargs)
..\venv\lib\site-packages\rest_framework\views.py:509: in dispatch
    response = self.handle_exception(exc)
..\venv\lib\site-packages\rest_framework\views.py:469: in handle_exception
    self.raise_uncaught_exception(exc)
..\venv\lib\site-packages\rest_framework\views.py:480: in raise_uncaught_exception
    raise exc
..\venv\lib\site-packages\rest_framework\views.py:506: in dispatch
    response = handler(request, *args, **kwargs)
api_yamdb\api\views.py:79: in post
    serializer.save(confirmation_code=confirmation_code,)
..\venv\lib\site-packages\rest_framework\serializers.py:205: in save
    self.instance = self.create(validated_data)
api_yamdb\api\serializers.py:122: in create
    return User.objects.create_user(**validated_data)
api_yamdb\users\models.py:36: in create_user
    user.save()
..\venv\lib\site-packages\django\contrib\auth\base_user.py:66: in save
    super().save(*args, **kwargs)
..\venv\lib\site-packages\django\db\models\base.py:744: in save
    force_update=force_update, update_fields=update_fields)
..\venv\lib\site-packages\django\db\models\base.py:782: in save_base
    force_update, using, update_fields,
..\venv\lib\site-packages\django\db\models\base.py:873: in _save_table
    result = self._do_insert(cls._base_manager, using, fields, update_pk, raw)
..\venv\lib\site-packages\django\db\models\base.py:911: in _do_insert
    using=using, raw=raw)
..\venv\lib\site-packages\django\db\models\manager.py:82: in manager_method
    return getattr(self.get_queryset(), name)(*args, **kwargs)
..\venv\lib\site-packages\django\db\models\query.py:1186: in _insert
    return query.get_compiler(using=using).execute_sql(return_id)
..\venv\lib\site-packages\django\db\models\sql\compiler.py:1377: in execute_sql
    cursor.execute(sql, params)
..\venv\lib\site-packages\django\db\backends\utils.py:67: in execute
    return self._execute_with_wrappers(sql, params, many=False, executor=self._execute)
..\venv\lib\site-packages\django\db\backends\utils.py:76: in _execute_with_wrappers
    return executor(sql, params, many, context)
..\venv\lib\site-packages\django\db\backends\utils.py:84: in _execute
    return self.cursor.execute(sql, params)
..\venv\lib\site-packages\django\db\utils.py:89: in __exit__
    raise dj_exc_value.with_traceback(traceback) from exc_value
..\venv\lib\site-packages\django\db\backends\utils.py:84: in _execute
    return self.cursor.execute(sql, params)
_ _ _ _ _ _ _ _ _ _ _ _ _ _ _ _ _ _ _ _ _ _ _ _ _ _ _ _ _ _ _ _ _ _ _ _ _ _ _ _

self = <django.db.backends.sqlite3.base.SQLiteCursorWrapper object at 0x05C6C088>
query = 'INSERT INTO "users_user" ("password", "last_login", "is_superuser", "first_name", "last_name", "is_staff", "is_active...rname", "email", "bio", "role", "is_moderator", "confirmation_code") VALUES (?, ?, ?, ?, ?, ?, ?, ?, ?, ?, ?, ?, ?, ?)'
params = ['pbkdf2_sha256$150000$YWvCxaVnbjvf$rq89ZoJ6nOdiyf9zC1lHChpYf7JAkoF1WbOHivZgrYk=', None, False, '', '', False, ...]

    def execute(self, query, params=None):
        if params is None:
            return Database.Cursor.execute(self, query)
        query = self.convert_query(query)
>       return Database.Cursor.execute(self, query, params)
E       django.db.utils.IntegrityError: UNIQUE constraint failed: users_user.email

..\venv\lib\site-packages\django\db\backends\sqlite3\base.py:383: IntegrityError
------------------------------ Captured log call ------------------------------
ERROR    django.request:log.py:228 Internal Server Error: /api/v1/auth/signup/
Traceback (most recent call last):
  File "e:\dev\s_10_project\venv\lib\site-packages\django\db\backends\utils.py", line 84, in _execute
    return self.cursor.execute(sql, params)
  File "e:\dev\s_10_project\venv\lib\site-packages\django\db\backends\sqlite3\base.py", line 383, in execute
    return Database.Cursor.execute(self, query, params)
sqlite3.IntegrityError: UNIQUE constraint failed: users_user.email

The above exception was the direct cause of the following exception:

Traceback (most recent call last):
  File "e:\dev\s_10_project\venv\lib\site-packages\django\core\handlers\exception.py", line 34, in inner
    response = get_response(request)
  File "e:\dev\s_10_project\venv\lib\site-packages\django\core\handlers\base.py", line 115, in _get_response
    response = self.process_exception_by_middleware(e, request)
  File "e:\dev\s_10_project\venv\lib\site-packages\django\core\handlers\base.py", line 113, in _get_response
    response = wrapped_callback(request, *callback_args, **callback_kwargs)
  File "e:\dev\s_10_project\venv\lib\site-packages\django\views\decorators\csrf.py", line 54, in wrapped_view
    return view_func(*args, **kwargs)
  File "e:\dev\s_10_project\venv\lib\site-packages\django\views\generic\base.py", line 71, in view
    return self.dispatch(request, *args, **kwargs)
  File "e:\dev\s_10_project\venv\lib\site-packages\rest_framework\views.py", line 509, in dispatch
    response = self.handle_exception(exc)
  File "e:\dev\s_10_project\venv\lib\site-packages\rest_framework\views.py", line 469, in handle_exception
    self.raise_uncaught_exception(exc)
  File "e:\dev\s_10_project\venv\lib\site-packages\rest_framework\views.py", line 480, in raise_uncaught_exception
    raise exc
  File "e:\dev\s_10_project\venv\lib\site-packages\rest_framework\views.py", line 506, in dispatch
    response = handler(request, *args, **kwargs)
  File "E:\Dev\s_10_project\api_yamdb\api_yamdb\api\views.py", line 79, in post
    serializer.save(confirmation_code=confirmation_code,)
  File "e:\dev\s_10_project\venv\lib\site-packages\rest_framework\serializers.py", line 205, in save
    self.instance = self.create(validated_data)
  File "E:\Dev\s_10_project\api_yamdb\api_yamdb\api\serializers.py", line 122, in create
    return User.objects.create_user(**validated_data)
  File "E:\Dev\s_10_project\api_yamdb\api_yamdb\users\models.py", line 36, in create_user
    user.save()
  File "e:\dev\s_10_project\venv\lib\site-packages\django\contrib\auth\base_user.py", line 66, in save
    super().save(*args, **kwargs)
  File "e:\dev\s_10_project\venv\lib\site-packages\django\db\models\base.py", line 744, in save
    force_update=force_update, update_fields=update_fields)
  File "e:\dev\s_10_project\venv\lib\site-packages\django\db\models\base.py", line 782, in save_base
    force_update, using, update_fields,
  File "e:\dev\s_10_project\venv\lib\site-packages\django\db\models\base.py", line 873, in _save_table
    result = self._do_insert(cls._base_manager, using, fields, update_pk, raw)
  File "e:\dev\s_10_project\venv\lib\site-packages\django\db\models\base.py", line 911, in _do_insert
    using=using, raw=raw)
  File "e:\dev\s_10_project\venv\lib\site-packages\django\db\models\manager.py", line 82, in manager_method
    return getattr(self.get_queryset(), name)(*args, **kwargs)
  File "e:\dev\s_10_project\venv\lib\site-packages\django\db\models\query.py", line 1186, in _insert
    return query.get_compiler(using=using).execute_sql(return_id)
  File "e:\dev\s_10_project\venv\lib\site-packages\django\db\models\sql\compiler.py", line 1377, in execute_sql
    cursor.execute(sql, params)
  File "e:\dev\s_10_project\venv\lib\site-packages\django\db\backends\utils.py", line 67, in execute
    return self._execute_with_wrappers(sql, params, many=False, executor=self._execute)
  File "e:\dev\s_10_project\venv\lib\site-packages\django\db\backends\utils.py", line 76, in _execute_with_wrappers
    return executor(sql, params, many, context)
  File "e:\dev\s_10_project\venv\lib\site-packages\django\db\backends\utils.py", line 84, in _execute
    return self.cursor.execute(sql, params)
  File "e:\dev\s_10_project\venv\lib\site-packages\django\db\utils.py", line 89, in __exit__
    raise dj_exc_value.with_traceback(traceback) from exc_value
  File "e:\dev\s_10_project\venv\lib\site-packages\django\db\backends\utils.py", line 84, in _execute
    return self.cursor.execute(sql, params)
  File "e:\dev\s_10_project\venv\lib\site-packages\django\db\backends\sqlite3\base.py", line 383, in execute
    return Database.Cursor.execute(self, query, params)
django.db.utils.IntegrityError: UNIQUE constraint failed: users_user.email
________________ Test01UserAPI.test_01_users_not_authenticated ________________

self = <tests.test_01_users.Test01UserAPI object at 0x0594AC10>
client = <django.test.client.Client object at 0x0615B7B0>

    @pytest.mark.django_db(transaction=True)
    def test_01_users_not_authenticated(self, client):
        response = client.get('/api/v1/users/')
    
        assert response.status_code != 404, (
            '—траница `/api/v1/users/` не найдена, проверьте этот адрес в *urls.py*'
        )
    
>       assert response.status_code == 401, (
            'ѕроверьте, что при GET запросе `/api/v1/users/` без токена авторизации возвращаетс€ статус 401'
        )
E       AssertionError: ѕроверьте, что при GET запросе `/api/v1/users/` без токена авторизации возвращаетс€ статус 401
E       assert 403 == 401
E         +403
E         -401

tests\test_01_users.py:17: AssertionError
------------------------------ Captured log call ------------------------------
WARNING  django.request:log.py:228 Forbidden: /api/v1/users/
___________ Test01UserAPI.test_02_users_username_not_authenticated ____________

self = <tests.test_01_users.Test01UserAPI object at 0x0583DE50>
client = <django.test.client.Client object at 0x05932990>
admin = <User: TestAdmin>

    @pytest.mark.django_db(transaction=True)
    def test_02_users_username_not_authenticated(self, client, admin):
        response = client.get(f'/api/v1/users/{admin.username}/')
    
>       assert response.status_code != 404, (
            '—траница `/api/v1/users/{username}/` не найдена, проверьте этот адрес в *urls.py*'
        )
E       AssertionError: —траница `/api/v1/users/{username}/` не найдена, проверьте этот адрес в *urls.py*
E       assert 404 != 404
E        +  where 404 = <HttpResponseNotFound status_code=404, "text/html">.status_code

tests\test_01_users.py:25: AssertionError
------------------------------ Captured log call ------------------------------
WARNING  django.request:log.py:228 Not Found: /api/v1/users/TestAdmin/
______________ Test01UserAPI.test_03_users_me_not_authenticated _______________

self = <tests.test_01_users.Test01UserAPI object at 0x0615B0B0>
client = <django.test.client.Client object at 0x0587D030>

    @pytest.mark.django_db(transaction=True)
    def test_03_users_me_not_authenticated(self, client):
>       response = client.get('/api/v1/users/me/')

tests\test_01_users.py:35: 
_ _ _ _ _ _ _ _ _ _ _ _ _ _ _ _ _ _ _ _ _ _ _ _ _ _ _ _ _ _ _ _ _ _ _ _ _ _ _ _
..\venv\lib\site-packages\django\test\client.py:535: in get
    response = super().get(path, data=data, secure=secure, **extra)
..\venv\lib\site-packages\django\test\client.py:347: in get
    **extra,
..\venv\lib\site-packages\django\test\client.py:422: in generic
    return self.request(**r)
..\venv\lib\site-packages\django\test\client.py:503: in request
    raise exc_value
..\venv\lib\site-packages\django\core\handlers\exception.py:34: in inner
    response = get_response(request)
..\venv\lib\site-packages\django\core\handlers\base.py:115: in _get_response
    response = self.process_exception_by_middleware(e, request)
..\venv\lib\site-packages\django\core\handlers\base.py:113: in _get_response
    response = wrapped_callback(request, *callback_args, **callback_kwargs)
..\venv\lib\site-packages\django\views\decorators\csrf.py:54: in wrapped_view
    return view_func(*args, **kwargs)
..\venv\lib\site-packages\django\views\generic\base.py:71: in view
    return self.dispatch(request, *args, **kwargs)
..\venv\lib\site-packages\rest_framework\views.py:509: in dispatch
    response = self.handle_exception(exc)
..\venv\lib\site-packages\rest_framework\views.py:469: in handle_exception
    self.raise_uncaught_exception(exc)
..\venv\lib\site-packages\rest_framework\views.py:480: in raise_uncaught_exception
    raise exc
..\venv\lib\site-packages\rest_framework\views.py:506: in dispatch
    response = handler(request, *args, **kwargs)
..\venv\lib\site-packages\rest_framework\generics.py:282: in get
    return self.retrieve(request, *args, **kwargs)
..\venv\lib\site-packages\rest_framework\mixins.py:54: in retrieve
    instance = self.get_object()
_ _ _ _ _ _ _ _ _ _ _ _ _ _ _ _ _ _ _ _ _ _ _ _ _ _ _ _ _ _ _ _ _ _ _ _ _ _ _ _

self = <api.views.UserDetail object at 0x05909370>

    def get_object(self):
        """
        Returns the object the view is displaying.
    
        You may want to override this if you need to provide non-standard
        queryset lookups.  Eg if objects are referenced using multiple
        keyword arguments in the url conf.
        """
        queryset = self.filter_queryset(self.get_queryset())
    
        # Perform the lookup filtering.
        lookup_url_kwarg = self.lookup_url_kwarg or self.lookup_field
    
        assert lookup_url_kwarg in self.kwargs, (
            'Expected view %s to be called with a URL keyword argument '
            'named "%s". Fix your URL conf, or set the `.lookup_field` '
            'attribute on the view correctly.' %
>           (self.__class__.__name__, lookup_url_kwarg)
        )
E       AssertionError: Expected view UserDetail to be called with a URL keyword argument named "pk". Fix your URL conf, or set the `.lookup_field` attribute on the view correctly.

..\venv\lib\site-packages\rest_framework\generics.py:92: AssertionError
------------------------------ Captured log call ------------------------------
ERROR    django.request:log.py:228 Internal Server Error: /api/v1/users/me/
Traceback (most recent call last):
  File "e:\dev\s_10_project\venv\lib\site-packages\django\core\handlers\exception.py", line 34, in inner
    response = get_response(request)
  File "e:\dev\s_10_project\venv\lib\site-packages\django\core\handlers\base.py", line 115, in _get_response
    response = self.process_exception_by_middleware(e, request)
  File "e:\dev\s_10_project\venv\lib\site-packages\django\core\handlers\base.py", line 113, in _get_response
    response = wrapped_callback(request, *callback_args, **callback_kwargs)
  File "e:\dev\s_10_project\venv\lib\site-packages\django\views\decorators\csrf.py", line 54, in wrapped_view
    return view_func(*args, **kwargs)
  File "e:\dev\s_10_project\venv\lib\site-packages\django\views\generic\base.py", line 71, in view
    return self.dispatch(request, *args, **kwargs)
  File "e:\dev\s_10_project\venv\lib\site-packages\rest_framework\views.py", line 509, in dispatch
    response = self.handle_exception(exc)
  File "e:\dev\s_10_project\venv\lib\site-packages\rest_framework\views.py", line 469, in handle_exception
    self.raise_uncaught_exception(exc)
  File "e:\dev\s_10_project\venv\lib\site-packages\rest_framework\views.py", line 480, in raise_uncaught_exception
    raise exc
  File "e:\dev\s_10_project\venv\lib\site-packages\rest_framework\views.py", line 506, in dispatch
    response = handler(request, *args, **kwargs)
  File "e:\dev\s_10_project\venv\lib\site-packages\rest_framework\generics.py", line 282, in get
    return self.retrieve(request, *args, **kwargs)
  File "e:\dev\s_10_project\venv\lib\site-packages\rest_framework\mixins.py", line 54, in retrieve
    instance = self.get_object()
  File "e:\dev\s_10_project\venv\lib\site-packages\rest_framework\generics.py", line 92, in get_object
    (self.__class__.__name__, lookup_url_kwarg)
AssertionError: Expected view UserDetail to be called with a URL keyword argument named "pk". Fix your URL conf, or set the `.lookup_field` attribute on the view correctly.
____________________ Test01UserAPI.test_04_users_get_admin ____________________

self = <tests.test_01_users.Test01UserAPI object at 0x05F4DEF0>
admin_client = <rest_framework.test.APIClient object at 0x0587D810>
admin = <User: TestAdmin>

    @pytest.mark.django_db(transaction=True)
    def test_04_users_get_admin(self, admin_client, admin):
        response = admin_client.get('/api/v1/users/')
        assert response.status_code != 404, (
            '—траница `/api/v1/users/` не найдена, проверьте этот адрес в *urls.py*'
        )
>       assert response.status_code == 200, (
            'ѕроверьте, что при GET запросе `/api/v1/users/` с токеном авторизации возвращаетс€ статус 200'
        )
E       AssertionError: ѕроверьте, что при GET запросе `/api/v1/users/` с токеном авторизации возвращаетс€ статус 200
E       assert 403 == 200
E         +403
E         -200

tests\test_01_users.py:51: AssertionError
------------------------------ Captured log call ------------------------------
WARNING  django.request:log.py:228 Forbidden: /api/v1/users/
__________________ Test01UserAPI.test_04_02_users_get_search __________________

self = <tests.test_01_users.Test01UserAPI object at 0x05806FB0>
admin_client = <rest_framework.test.APIClient object at 0x05932950>
admin = <User: TestAdmin>

    @pytest.mark.django_db(transaction=True)
    def test_04_02_users_get_search(self, admin_client, admin):
        url = '/api/v1/users/'
        search_url = f'{url}?search={admin.username}'
        response = admin_client.get(search_url)
        assert response.status_code != 404, (
            '—траница `/api/v1/users/?search={username}` не найдена, проверьте этот адрес в *urls.py*'
        )
        reponse_json = response.json()
>       assert 'results' in reponse_json and isinstance(reponse_json.get('results'), list), (
            'ѕроверьте, что при GET запросе `/api/v1/users/?search={username}` '
            'результаты возвращаютс€ под ключом `results` и в виде списка.'
        )
E       AssertionError: ѕроверьте, что при GET запросе `/api/v1/users/?search={username}` результаты возвращаютс€ под ключом `results` и в виде списка.
E       assert ('results' in {'detail': 'You do not have permission to perform this action.'})

tests\test_01_users.py:97: AssertionError
------------------------------ Captured log call ------------------------------
WARNING  django.request:log.py:228 Forbidden: /api/v1/users/
__________________ Test01UserAPI.test_05_01_users_post_admin __________________

self = <tests.test_01_users.Test01UserAPI object at 0x05EC4B30>
admin_client = <rest_framework.test.APIClient object at 0x05FFE730>
admin = <User: TestAdmin>

    @pytest.mark.django_db(transaction=True)
    def test_05_01_users_post_admin(self, admin_client, admin):
        empty_data = {}
        response = admin_client.post('/api/v1/users/', data=empty_data)
>       assert response.status_code == 400, (
            'ѕроверьте, что при POST запросе `/api/v1/users/` с пустыми данными возвращаетe 400'
        )
E       AssertionError: ѕроверьте, что при POST запросе `/api/v1/users/` с пустыми данными возвращаетe 400
E       assert 403 == 400
E         +403
E         -400

tests\test_01_users.py:135: AssertionError
------------------------------ Captured log call ------------------------------
WARNING  django.request:log.py:228 Forbidden: /api/v1/users/
_______________ Test01UserAPI.test_06_users_username_get_admin ________________

self = <tests.test_01_users.Test01UserAPI object at 0x05FFE9D0>
admin_client = <rest_framework.test.APIClient object at 0x0587D4B0>
admin = <User: TestAdmin>

    @pytest.mark.django_db(transaction=True)
    def test_06_users_username_get_admin(self, admin_client, admin):
>       user, moderator = create_users_api(admin_client)

tests\test_01_users.py:272: 
_ _ _ _ _ _ _ _ _ _ _ _ _ _ _ _ _ _ _ _ _ _ _ _ _ _ _ _ _ _ _ _ _ _ _ _ _ _ _ _
tests\common.py:13: in create_users_api
    user = get_user_model().objects.get(username=data['username'])
..\venv\lib\site-packages\django\db\models\manager.py:82: in manager_method
    return getattr(self.get_queryset(), name)(*args, **kwargs)
_ _ _ _ _ _ _ _ _ _ _ _ _ _ _ _ _ _ _ _ _ _ _ _ _ _ _ _ _ _ _ _ _ _ _ _ _ _ _ _

self = <QuerySet [<User: TestAdmin>]>, args = ()
kwargs = {'username': 'TestUser'}, clone = <QuerySet []>, num = 0

    def get(self, *args, **kwargs):
        """
        Perform the query and return a single object matching the given
        keyword arguments.
        """
        clone = self.filter(*args, **kwargs)
        if self.query.can_filter() and not self.query.distinct_fields:
            clone = clone.order_by()
        num = len(clone)
        if num == 1:
            return clone._result_cache[0]
        if not num:
            raise self.model.DoesNotExist(
                "%s matching query does not exist." %
>               self.model._meta.object_name
            )
E           users.models.User.DoesNotExist: User matching query does not exist.

..\venv\lib\site-packages\django\db\models\query.py:408: DoesNotExist
------------------------------ Captured log call ------------------------------
WARNING  django.request:log.py:228 Forbidden: /api/v1/users/
_____________ Test01UserAPI.test_06_users_username_get_not_admin ______________

self = <tests.test_01_users.Test01UserAPI object at 0x05AE2850>
moderator_client = <rest_framework.test.APIClient object at 0x05A227B0>
admin = <User: TestAdmin>

    @pytest.mark.django_db(transaction=True)
    def test_06_users_username_get_not_admin(self, moderator_client, admin):
        response = moderator_client.get(f'/api/v1/users/{admin.username}/')
>       assert response.status_code != 404, (
            '—траница `/api/v1/users/{username}/` не найдена, проверьте этот адрес в *urls.py*'
        )
E       AssertionError: —траница `/api/v1/users/{username}/` не найдена, проверьте этот адрес в *urls.py*
E       assert 404 != 404
E        +  where 404 = <HttpResponseNotFound status_code=404, "text/html">.status_code

tests\test_01_users.py:315: AssertionError
------------------------------ Captured log call ------------------------------
WARNING  django.request:log.py:228 Not Found: /api/v1/users/TestAdmin/
_____________ Test01UserAPI.test_07_01_users_username_patch_admin _____________

self = <tests.test_01_users.Test01UserAPI object at 0x05A365F0>
admin_client = <rest_framework.test.APIClient object at 0x05A36830>
admin = <User: TestAdmin>

    @pytest.mark.django_db(transaction=True)
    def test_07_01_users_username_patch_admin(self, admin_client, admin):
>       user, moderator = create_users_api(admin_client)

tests\test_01_users.py:326: 
_ _ _ _ _ _ _ _ _ _ _ _ _ _ _ _ _ _ _ _ _ _ _ _ _ _ _ _ _ _ _ _ _ _ _ _ _ _ _ _
tests\common.py:13: in create_users_api
    user = get_user_model().objects.get(username=data['username'])
..\venv\lib\site-packages\django\db\models\manager.py:82: in manager_method
    return getattr(self.get_queryset(), name)(*args, **kwargs)
_ _ _ _ _ _ _ _ _ _ _ _ _ _ _ _ _ _ _ _ _ _ _ _ _ _ _ _ _ _ _ _ _ _ _ _ _ _ _ _

self = <QuerySet [<User: TestAdmin>]>, args = ()
kwargs = {'username': 'TestUser'}, clone = <QuerySet []>, num = 0

    def get(self, *args, **kwargs):
        """
        Perform the query and return a single object matching the given
        keyword arguments.
        """
        clone = self.filter(*args, **kwargs)
        if self.query.can_filter() and not self.query.distinct_fields:
            clone = clone.order_by()
        num = len(clone)
        if num == 1:
            return clone._result_cache[0]
        if not num:
            raise self.model.DoesNotExist(
                "%s matching query does not exist." %
>               self.model._meta.object_name
            )
E           users.models.User.DoesNotExist: User matching query does not exist.

..\venv\lib\site-packages\django\db\models\query.py:408: DoesNotExist
------------------------------ Captured log call ------------------------------
WARNING  django.request:log.py:228 Forbidden: /api/v1/users/
___________ Test01UserAPI.test_07_02_users_username_patch_moderator ___________

self = <tests.test_01_users.Test01UserAPI object at 0x05A36B90>
moderator_client = <rest_framework.test.APIClient object at 0x05834EF0>
user = <User: TestUser>

    @pytest.mark.django_db(transaction=True)
    def test_07_02_users_username_patch_moderator(self, moderator_client, user):
        data = {
            'first_name': 'New USer Firstname',
            'last_name': 'New USer Lastname',
            'bio': 'new user bio'
        }
        response = moderator_client.patch(f'/api/v1/users/{user.username}/', data=data)
>       assert response.status_code == 403, (
            'ѕроверьте, что при PATCH запросе `/api/v1/users/{username}/` '
            'пользователь с ролью moderator не может измен€ть данные других пользователей'
        )
E       AssertionError: ѕроверьте, что при PATCH запросе `/api/v1/users/{username}/` пользователь с ролью moderator не может измен€ть данные других пользователей
E       assert 404 == 403
E         +404
E         -403

tests\test_01_users.py:364: AssertionError
------------------------------ Captured log call ------------------------------
WARNING  django.request:log.py:228 Not Found: /api/v1/users/TestUser/
_____________ Test01UserAPI.test_07_03_users_username_patch_user ______________

self = <tests.test_01_users.Test01UserAPI object at 0x05834450>
user_client = <rest_framework.test.APIClient object at 0x058C12F0>
user = <User: TestUser>

    @pytest.mark.django_db(transaction=True)
    def test_07_03_users_username_patch_user(self, user_client, user):
        data = {
            'first_name': 'New USer Firstname',
            'last_name': 'New USer Lastname',
            'bio': 'new user bio'
        }
        response = user_client.patch(f'/api/v1/users/{user.username}/', data=data)
>       assert response.status_code == 403, (
            'ѕроверьте, что при PATCH запросе `/api/v1/users/{username}/` '
            'пользователь с ролью user не может измен€ть данные других пользователей'
        )
E       AssertionError: ѕроверьте, что при PATCH запросе `/api/v1/users/{username}/` пользователь с ролью user не может измен€ть данные других пользователей
E       assert 404 == 403
E         +404
E         -403

tests\test_01_users.py:377: AssertionError
------------------------------ Captured log call ------------------------------
WARNING  django.request:log.py:228 Not Found: /api/v1/users/TestUser/
_________ Test01UserAPI.test_07_05_users_username_put_user_restricted _________

self = <tests.test_01_users.Test01UserAPI object at 0x05D35790>
user_client = <rest_framework.test.APIClient object at 0x05EACB10>
user = <User: TestUser>

    @pytest.mark.django_db(transaction=True)
    def test_07_05_users_username_put_user_restricted(self, user_client, user):
        data = {
            'first_name': 'New USer Firstname',
            'last_name': 'New USer Lastname',
            'bio': 'new user bio'
        }
        response = user_client.put(f'/api/v1/users/{user.username}/', data=data)
        code = 403
>       assert response.status_code == code, (
            'ѕроверьте, что PUT запрос на `/api/v1/users/{username}/` '
            f'не доступен и возвращаетс€ статус {code}'
        )
E       AssertionError: ѕроверьте, что PUT запрос на `/api/v1/users/{username}/` не доступен и возвращаетс€ статус 403
E       assert 404 == 403
E         +404
E         -403

tests\test_01_users.py:391: AssertionError
------------------------------ Captured log call ------------------------------
WARNING  django.request:log.py:228 Not Found: /api/v1/users/TestUser/
____________ Test01UserAPI.test_08_01_users_username_delete_admin _____________

self = <tests.test_01_users.Test01UserAPI object at 0x058DE4D0>
admin_client = <rest_framework.test.APIClient object at 0x05C56430>

    @pytest.mark.django_db(transaction=True)
    def test_08_01_users_username_delete_admin(self, admin_client):
>       user, moderator = create_users_api(admin_client)

tests\test_01_users.py:398: 
_ _ _ _ _ _ _ _ _ _ _ _ _ _ _ _ _ _ _ _ _ _ _ _ _ _ _ _ _ _ _ _ _ _ _ _ _ _ _ _
tests\common.py:13: in create_users_api
    user = get_user_model().objects.get(username=data['username'])
..\venv\lib\site-packages\django\db\models\manager.py:82: in manager_method
    return getattr(self.get_queryset(), name)(*args, **kwargs)
_ _ _ _ _ _ _ _ _ _ _ _ _ _ _ _ _ _ _ _ _ _ _ _ _ _ _ _ _ _ _ _ _ _ _ _ _ _ _ _

self = <QuerySet [<User: TestAdmin>]>, args = ()
kwargs = {'username': 'TestUser'}, clone = <QuerySet []>, num = 0

    def get(self, *args, **kwargs):
        """
        Perform the query and return a single object matching the given
        keyword arguments.
        """
        clone = self.filter(*args, **kwargs)
        if self.query.can_filter() and not self.query.distinct_fields:
            clone = clone.order_by()
        num = len(clone)
        if num == 1:
            return clone._result_cache[0]
        if not num:
            raise self.model.DoesNotExist(
                "%s matching query does not exist." %
>               self.model._meta.object_name
            )
E           users.models.User.DoesNotExist: User matching query does not exist.

..\venv\lib\site-packages\django\db\models\query.py:408: DoesNotExist
------------------------------ Captured log call ------------------------------
WARNING  django.request:log.py:228 Forbidden: /api/v1/users/
__________ Test01UserAPI.test_08_02_users_username_delete_moderator ___________

self = <tests.test_01_users.Test01UserAPI object at 0x0599DB70>
moderator_client = <rest_framework.test.APIClient object at 0x059551F0>
user = <User: TestUser>

    @pytest.mark.django_db(transaction=True)
    def test_08_02_users_username_delete_moderator(self, moderator_client, user):
        users_before = get_user_model().objects.count()
        response = moderator_client.delete(f'/api/v1/users/{user.username}/')
>       assert response.status_code == 403, (
            'ѕроверьте, что при DELETE запросе `/api/v1/users/{username}/`'
            'не от админа, возвращаете статус 403'
        )
E       AssertionError: ѕроверьте, что при DELETE запросе `/api/v1/users/{username}/`не от админа, возвращаете статус 403
E       assert 404 == 403
E         +404
E         -403

tests\test_01_users.py:411: AssertionError
------------------------------ Captured log call ------------------------------
WARNING  django.request:log.py:228 Not Found: /api/v1/users/TestUser/
_____________ Test01UserAPI.test_08_03_users_username_delete_user _____________

self = <tests.test_01_users.Test01UserAPI object at 0x0586DF30>
user_client = <rest_framework.test.APIClient object at 0x05960350>
user = <User: TestUser>

    @pytest.mark.django_db(transaction=True)
    def test_08_03_users_username_delete_user(self, user_client, user):
        users_before = get_user_model().objects.count()
        response = user_client.delete(f'/api/v1/users/{user.username}/')
>       assert response.status_code == 403, (
            'ѕроверьте, что при DELETE запросе `/api/v1/users/{username}/` '
            'не от админа, возвращаете статус 403'
        )
E       AssertionError: ѕроверьте, что при DELETE запросе `/api/v1/users/{username}/` не от админа, возвращаете статус 403
E       assert 404 == 403
E         +404
E         -403

tests\test_01_users.py:424: AssertionError
------------------------------ Captured log call ------------------------------
WARNING  django.request:log.py:228 Not Found: /api/v1/users/TestUser/
__________ Test01UserAPI.test_08_04_users_username_delete_superuser ___________

self = <tests.test_01_users.Test01UserAPI object at 0x05960690>
user_superuser_client = <rest_framework.test.APIClient object at 0x058C65F0>
user = <User: TestUser>

    @pytest.mark.django_db(transaction=True)
    def test_08_04_users_username_delete_superuser(self, user_superuser_client, user):
        users_before = get_user_model().objects.count()
        response = user_superuser_client.delete(f'/api/v1/users/{user.username}/')
        code = 204
>       assert response.status_code == code, (
            'ѕроверьте, что при DELETE запросе `/api/v1/users/{username}/` '
            f'от суперпользовател€, возвращаете статус {code}'
        )
E       AssertionError: ѕроверьте, что при DELETE запросе `/api/v1/users/{username}/` от суперпользовател€, возвращаете статус 204
E       assert 404 == 204
E         +404
E         -204

tests\test_01_users.py:438: AssertionError
------------------------------ Captured log call ------------------------------
WARNING  django.request:log.py:228 Not Found: /api/v1/users/TestUser/
________________ Test01UserAPI.test_09_users_check_permissions ________________

self = <tests.test_01_users.Test01UserAPI object at 0x05C6B390>
admin_client = <rest_framework.test.APIClient object at 0x05F4DE90>
admin = <User: TestAdmin>

    @pytest.mark.django_db(transaction=True)
    def test_09_users_check_permissions(self, admin_client, admin):
>       user, moderator = create_users_api(admin_client)

tests\test_01_users.py:488: 
_ _ _ _ _ _ _ _ _ _ _ _ _ _ _ _ _ _ _ _ _ _ _ _ _ _ _ _ _ _ _ _ _ _ _ _ _ _ _ _
tests\common.py:13: in create_users_api
    user = get_user_model().objects.get(username=data['username'])
..\venv\lib\site-packages\django\db\models\manager.py:82: in manager_method
    return getattr(self.get_queryset(), name)(*args, **kwargs)
_ _ _ _ _ _ _ _ _ _ _ _ _ _ _ _ _ _ _ _ _ _ _ _ _ _ _ _ _ _ _ _ _ _ _ _ _ _ _ _

self = <QuerySet [<User: TestAdmin>]>, args = ()
kwargs = {'username': 'TestUser'}, clone = <QuerySet []>, num = 0

    def get(self, *args, **kwargs):
        """
        Perform the query and return a single object matching the given
        keyword arguments.
        """
        clone = self.filter(*args, **kwargs)
        if self.query.can_filter() and not self.query.distinct_fields:
            clone = clone.order_by()
        num = len(clone)
        if num == 1:
            return clone._result_cache[0]
        if not num:
            raise self.model.DoesNotExist(
                "%s matching query does not exist." %
>               self.model._meta.object_name
            )
E           users.models.User.DoesNotExist: User matching query does not exist.

..\venv\lib\site-packages\django\db\models\query.py:408: DoesNotExist
------------------------------ Captured log call ------------------------------
WARNING  django.request:log.py:228 Forbidden: /api/v1/users/
__________________ Test01UserAPI.test_10_users_me_get_admin ___________________

self = <tests.test_01_users.Test01UserAPI object at 0x05A08AB0>
admin_client = <rest_framework.test.APIClient object at 0x0579B250>
admin = <User: TestAdmin>

    @pytest.mark.django_db(transaction=True)
    def test_10_users_me_get_admin(self, admin_client, admin):
>       user, moderator = create_users_api(admin_client)

tests\test_01_users.py:494: 
_ _ _ _ _ _ _ _ _ _ _ _ _ _ _ _ _ _ _ _ _ _ _ _ _ _ _ _ _ _ _ _ _ _ _ _ _ _ _ _
tests\common.py:13: in create_users_api
    user = get_user_model().objects.get(username=data['username'])
..\venv\lib\site-packages\django\db\models\manager.py:82: in manager_method
    return getattr(self.get_queryset(), name)(*args, **kwargs)
_ _ _ _ _ _ _ _ _ _ _ _ _ _ _ _ _ _ _ _ _ _ _ _ _ _ _ _ _ _ _ _ _ _ _ _ _ _ _ _

self = <QuerySet [<User: TestAdmin>]>, args = ()
kwargs = {'username': 'TestUser'}, clone = <QuerySet []>, num = 0

    def get(self, *args, **kwargs):
        """
        Perform the query and return a single object matching the given
        keyword arguments.
        """
        clone = self.filter(*args, **kwargs)
        if self.query.can_filter() and not self.query.distinct_fields:
            clone = clone.order_by()
        num = len(clone)
        if num == 1:
            return clone._result_cache[0]
        if not num:
            raise self.model.DoesNotExist(
                "%s matching query does not exist." %
>               self.model._meta.object_name
            )
E           users.models.User.DoesNotExist: User matching query does not exist.

..\venv\lib\site-packages\django\db\models\query.py:408: DoesNotExist
------------------------------ Captured log call ------------------------------
WARNING  django.request:log.py:228 Forbidden: /api/v1/users/
________________ Test01UserAPI.test_11_01_users_me_patch_admin ________________

self = <tests.test_01_users.Test01UserAPI object at 0x05C56170>
admin_client = <rest_framework.test.APIClient object at 0x058D3BB0>

    @pytest.mark.django_db(transaction=True)
    def test_11_01_users_me_patch_admin(self, admin_client):
>       user, moderator = create_users_api(admin_client)

tests\test_01_users.py:528: 
_ _ _ _ _ _ _ _ _ _ _ _ _ _ _ _ _ _ _ _ _ _ _ _ _ _ _ _ _ _ _ _ _ _ _ _ _ _ _ _
tests\common.py:13: in create_users_api
    user = get_user_model().objects.get(username=data['username'])
..\venv\lib\site-packages\django\db\models\manager.py:82: in manager_method
    return getattr(self.get_queryset(), name)(*args, **kwargs)
_ _ _ _ _ _ _ _ _ _ _ _ _ _ _ _ _ _ _ _ _ _ _ _ _ _ _ _ _ _ _ _ _ _ _ _ _ _ _ _

self = <QuerySet [<User: TestAdmin>]>, args = ()
kwargs = {'username': 'TestUser'}, clone = <QuerySet []>, num = 0

    def get(self, *args, **kwargs):
        """
        Perform the query and return a single object matching the given
        keyword arguments.
        """
        clone = self.filter(*args, **kwargs)
        if self.query.can_filter() and not self.query.distinct_fields:
            clone = clone.order_by()
        num = len(clone)
        if num == 1:
            return clone._result_cache[0]
        if not num:
            raise self.model.DoesNotExist(
                "%s matching query does not exist." %
>               self.model._meta.object_name
            )
E           users.models.User.DoesNotExist: User matching query does not exist.

..\venv\lib\site-packages\django\db\models\query.py:408: DoesNotExist
------------------------------ Captured log call ------------------------------
WARNING  django.request:log.py:228 Forbidden: /api/v1/users/
________________ Test01UserAPI.test_11_02_users_me_patch_user _________________

self = <tests.test_01_users.Test01UserAPI object at 0x05FF1D30>
user_client = <rest_framework.test.APIClient object at 0x05C6E3B0>

    @pytest.mark.django_db(transaction=True)
    def test_11_02_users_me_patch_user(self, user_client):
        data = {
            'first_name': 'New user first name',
            'last_name': 'New user last name',
            'bio': 'new user bio',
        }
>       response = user_client.patch('/api/v1/users/me/', data=data)

tests\test_01_users.py:559: 
_ _ _ _ _ _ _ _ _ _ _ _ _ _ _ _ _ _ _ _ _ _ _ _ _ _ _ _ _ _ _ _ _ _ _ _ _ _ _ _
..\venv\lib\site-packages\rest_framework\test.py:312: in patch
    path, data=data, format=format, content_type=content_type, **extra)
..\venv\lib\site-packages\rest_framework\test.py:217: in patch
    return self.generic('PATCH', path, data, content_type, **extra)
..\venv\lib\site-packages\rest_framework\test.py:234: in generic
    method, path, data, content_type, secure, **extra)
..\venv\lib\site-packages\django\test\client.py:422: in generic
    return self.request(**r)
..\venv\lib\site-packages\rest_framework\test.py:285: in request
    return super().request(**kwargs)
..\venv\lib\site-packages\rest_framework\test.py:237: in request
    request = super().request(**kwargs)
..\venv\lib\site-packages\django\test\client.py:503: in request
    raise exc_value
..\venv\lib\site-packages\django\core\handlers\exception.py:34: in inner
    response = get_response(request)
..\venv\lib\site-packages\django\core\handlers\base.py:115: in _get_response
    response = self.process_exception_by_middleware(e, request)
..\venv\lib\site-packages\django\core\handlers\base.py:113: in _get_response
    response = wrapped_callback(request, *callback_args, **callback_kwargs)
..\venv\lib\site-packages\django\views\decorators\csrf.py:54: in wrapped_view
    return view_func(*args, **kwargs)
..\venv\lib\site-packages\django\views\generic\base.py:71: in view
    return self.dispatch(request, *args, **kwargs)
..\venv\lib\site-packages\rest_framework\views.py:509: in dispatch
    response = self.handle_exception(exc)
..\venv\lib\site-packages\rest_framework\views.py:469: in handle_exception
    self.raise_uncaught_exception(exc)
..\venv\lib\site-packages\rest_framework\views.py:480: in raise_uncaught_exception
    raise exc
..\venv\lib\site-packages\rest_framework\views.py:506: in dispatch
    response = handler(request, *args, **kwargs)
..\venv\lib\site-packages\rest_framework\generics.py:288: in patch
    return self.partial_update(request, *args, **kwargs)
..\venv\lib\site-packages\rest_framework\mixins.py:82: in partial_update
    return self.update(request, *args, **kwargs)
..\venv\lib\site-packages\rest_framework\mixins.py:65: in update
    instance = self.get_object()
_ _ _ _ _ _ _ _ _ _ _ _ _ _ _ _ _ _ _ _ _ _ _ _ _ _ _ _ _ _ _ _ _ _ _ _ _ _ _ _

self = <api.views.UserDetail object at 0x05857D90>

    def get_object(self):
        """
        Returns the object the view is displaying.
    
        You may want to override this if you need to provide non-standard
        queryset lookups.  Eg if objects are referenced using multiple
        keyword arguments in the url conf.
        """
        queryset = self.filter_queryset(self.get_queryset())
    
        # Perform the lookup filtering.
        lookup_url_kwarg = self.lookup_url_kwarg or self.lookup_field
    
        assert lookup_url_kwarg in self.kwargs, (
            'Expected view %s to be called with a URL keyword argument '
            'named "%s". Fix your URL conf, or set the `.lookup_field` '
            'attribute on the view correctly.' %
>           (self.__class__.__name__, lookup_url_kwarg)
        )
E       AssertionError: Expected view UserDetail to be called with a URL keyword argument named "pk". Fix your URL conf, or set the `.lookup_field` attribute on the view correctly.

..\venv\lib\site-packages\rest_framework\generics.py:92: AssertionError
------------------------------ Captured log call ------------------------------
ERROR    django.request:log.py:228 Internal Server Error: /api/v1/users/me/
Traceback (most recent call last):
  File "e:\dev\s_10_project\venv\lib\site-packages\django\core\handlers\exception.py", line 34, in inner
    response = get_response(request)
  File "e:\dev\s_10_project\venv\lib\site-packages\django\core\handlers\base.py", line 115, in _get_response
    response = self.process_exception_by_middleware(e, request)
  File "e:\dev\s_10_project\venv\lib\site-packages\django\core\handlers\base.py", line 113, in _get_response
    response = wrapped_callback(request, *callback_args, **callback_kwargs)
  File "e:\dev\s_10_project\venv\lib\site-packages\django\views\decorators\csrf.py", line 54, in wrapped_view
    return view_func(*args, **kwargs)
  File "e:\dev\s_10_project\venv\lib\site-packages\django\views\generic\base.py", line 71, in view
    return self.dispatch(request, *args, **kwargs)
  File "e:\dev\s_10_project\venv\lib\site-packages\rest_framework\views.py", line 509, in dispatch
    response = self.handle_exception(exc)
  File "e:\dev\s_10_project\venv\lib\site-packages\rest_framework\views.py", line 469, in handle_exception
    self.raise_uncaught_exception(exc)
  File "e:\dev\s_10_project\venv\lib\site-packages\rest_framework\views.py", line 480, in raise_uncaught_exception
    raise exc
  File "e:\dev\s_10_project\venv\lib\site-packages\rest_framework\views.py", line 506, in dispatch
    response = handler(request, *args, **kwargs)
  File "e:\dev\s_10_project\venv\lib\site-packages\rest_framework\generics.py", line 288, in patch
    return self.partial_update(request, *args, **kwargs)
  File "e:\dev\s_10_project\venv\lib\site-packages\rest_framework\mixins.py", line 82, in partial_update
    return self.update(request, *args, **kwargs)
  File "e:\dev\s_10_project\venv\lib\site-packages\rest_framework\mixins.py", line 65, in update
    instance = self.get_object()
  File "e:\dev\s_10_project\venv\lib\site-packages\rest_framework\generics.py", line 92, in get_object
    (self.__class__.__name__, lookup_url_kwarg)
AssertionError: Expected view UserDetail to be called with a URL keyword argument named "pk". Fix your URL conf, or set the `.lookup_field` attribute on the view correctly.
_______________ Test02CategoryAPI.test_03_category_delete_admin _______________

self = <tests.test_02_category.Test02CategoryAPI object at 0x05A59F90>
admin_client = <rest_framework.test.APIClient object at 0x05996950>

    @pytest.mark.django_db(transaction=True)
    def test_03_category_delete_admin(self, admin_client):
        create_categories(admin_client)
        response = admin_client.delete('/api/v1/categories/books/')
>       assert response.status_code == 204, (
            'ѕроверьте, что при DELETE запросе `/api/v1/categories/{slug}/` возвращаете статус 204'
        )
E       AssertionError: ѕроверьте, что при DELETE запросе `/api/v1/categories/{slug}/` возвращаете статус 204
E       assert 403 == 204
E         +403
E         -204

tests\test_02_category.py:96: AssertionError
------------------------------ Captured log call ------------------------------
WARNING  django.request:log.py:228 Forbidden: /api/v1/categories/books/
__________ Test02CategoryAPI.test_04_category_check_permission_admin __________

self = <tests.test_02_category.Test02CategoryAPI object at 0x059DB0B0>
client = <django.test.client.Client object at 0x05932190>
admin_client = <rest_framework.test.APIClient object at 0x059323D0>

    @pytest.mark.django_db(transaction=True)
    def test_04_category_check_permission_admin(self, client, admin_client):
        categories = create_categories(admin_client)
        data = {
            'name': 'ћузыка',
            'slug': 'music'
        }
        response = client.post('/api/v1/categories/', data=data)
>       assert response.status_code == 401, (
            'ѕроверьте, что при POST запросе `/api/v1/categories/` '
            'без токена авторизации возвращаетс€ статус 401'
        )
E       AssertionError: ѕроверьте, что при POST запросе `/api/v1/categories/` без токена авторизации возвращаетс€ статус 401
E       assert 201 == 401
E         +201
E         -401

tests\test_02_category.py:141: AssertionError
_______________ Test02CategoryAPI.test_05_category_create_user ________________

self = <tests.test_02_category.Test02CategoryAPI object at 0x059DBE10>
user_client = <rest_framework.test.APIClient object at 0x05909610>

    @pytest.mark.django_db(transaction=True)
    def test_05_category_create_user(self, user_client):
        url = '/api/v1/categories/'
        data = {
            'name': '¬с€кое разное',
            'slug': 'something'
        }
        response = user_client.post(url, data=data)
        code = 403
>       assert response.status_code == code, (
            f'ѕроверьте, что при POST запросе на `{url}`, создание категорий недоступно дл€ '
            f'пользовател€ с ролью user'
        )
E       AssertionError: ѕроверьте, что при POST запросе на `/api/v1/categories/`, создание категорий недоступно дл€ пользовател€ с ролью user
E       assert 201 == 403
E         +201
E         -403

tests\test_02_category.py:163: AssertionError
_____________ Test02CategoryAPI.test_06_category_create_moderator _____________

self = <tests.test_02_category.Test02CategoryAPI object at 0x059095D0>
moderator_client = <rest_framework.test.APIClient object at 0x0615BC30>

    @pytest.mark.django_db(transaction=True)
    def test_06_category_create_moderator(self, moderator_client):
        url = '/api/v1/categories/'
        data = {
            'name': '¬с€кое разное',
            'slug': 'something'
        }
        response = moderator_client.post(url, data=data)
        code = 403
>       assert response.status_code == code, (
            f'ѕроверьте, что при POST запросе на `{url}`, создание категорий недоступно дл€ '
            f'пользовател€ с ролью moderator'
        )
E       AssertionError: ѕроверьте, что при POST запросе на `/api/v1/categories/`, создание категорий недоступно дл€ пользовател€ с ролью moderator
E       assert 201 == 403
E         +201
E         -403

tests\test_02_category.py:177: AssertionError
____________________ Test03GenreAPI.test_03_genres_delete _____________________

self = <tests.test_03_genre.Test03GenreAPI object at 0x059C4030>
admin_client = <rest_framework.test.APIClient object at 0x0589E4F0>

    @pytest.mark.django_db(transaction=True)
    def test_03_genres_delete(self, admin_client):
        genres = create_genre(admin_client)
        response = admin_client.delete(f'/api/v1/genres/{genres[0]["slug"]}/')
>       assert response.status_code == 204, (
            'ѕроверьте, что при DELETE запросе `/api/v1/genres/{slug}/` возвращаете статус 204'
        )
E       AssertionError: ѕроверьте, что при DELETE запросе `/api/v1/genres/{slug}/` возвращаете статус 204
E       assert 403 == 204
E         +403
E         -204

tests\test_03_genre.py:87: AssertionError
------------------------------ Captured log call ------------------------------
WARNING  django.request:log.py:228 Forbidden: /api/v1/genres/horror/
_______________ Test03GenreAPI.test_04_genres_check_permission ________________

self = <tests.test_03_genre.Test03GenreAPI object at 0x05827610>
client = <django.test.client.Client object at 0x059286F0>
admin_client = <rest_framework.test.APIClient object at 0x05928170>

    @pytest.mark.django_db(transaction=True)
    def test_04_genres_check_permission(self, client, admin_client):
        genres = create_genre(admin_client)
        data = {
            'name': 'Ѕоевик',
            'slug': 'action'
        }
        response = client.post('/api/v1/genres/', data=data)
>       assert response.status_code == 401, (
            'ѕроверьте, что при POST запросе `/api/v1/genres/` '
            'без токена авторизации возвращаетс€ статус 401'
        )
E       AssertionError: ѕроверьте, что при POST запросе `/api/v1/genres/` без токена авторизации возвращаетс€ статус 401
E       assert 201 == 401
E         +201
E         -401

tests\test_03_genre.py:129: AssertionError
__________________ Test03GenreAPI.test_05_genre_create_user ___________________

self = <tests.test_03_genre.Test03GenreAPI object at 0x058B8AB0>
user_client = <rest_framework.test.APIClient object at 0x0584B910>

    @pytest.mark.django_db(transaction=True)
    def test_05_genre_create_user(self, user_client):
        url = '/api/v1/genres/'
        data = {
            'name': '¬с€кое разное',
            'slug': 'something'
        }
        response = user_client.post(url, data=data)
        code = 403
>       assert response.status_code == code, (
            f'ѕроверьте, что при POST запросе на `{url}`, создание жанров недоступно дл€ '
            f'пользовател€ с ролью user'
        )
E       AssertionError: ѕроверьте, что при POST запросе на `/api/v1/genres/`, создание жанров недоступно дл€ пользовател€ с ролью user
E       assert 201 == 403
E         +201
E         -403

tests\test_03_genre.py:151: AssertionError
________________ Test03GenreAPI.test_06_genre_create_moderator ________________

self = <tests.test_03_genre.Test03GenreAPI object at 0x0593E2B0>
moderator_client = <rest_framework.test.APIClient object at 0x0593EBB0>

    @pytest.mark.django_db(transaction=True)
    def test_06_genre_create_moderator(self, moderator_client):
        url = '/api/v1/genres/'
        data = {
            'name': '¬с€кое разное',
            'slug': 'something'
        }
        response = moderator_client.post(url, data=data)
        code = 403
>       assert response.status_code == code, (
            f'ѕроверьте, что при POST запросе на `{url}`, создание жанров недоступно дл€ '
            f'пользовател€ с ролью moderator'
        )
E       AssertionError: ѕроверьте, что при POST запросе на `/api/v1/genres/`, создание жанров недоступно дл€ пользовател€ с ролью moderator
E       assert 201 == 403
E         +201
E         -403

tests\test_03_genre.py:165: AssertionError
_____________________ Test04TitleAPI.test_02_title_admin ______________________

self = <tests.test_04_title.Test04TitleAPI object at 0x058864B0>
admin_client = <rest_framework.test.APIClient object at 0x05825F50>

    @pytest.mark.django_db(transaction=True)
    def test_02_title_admin(self, admin_client):
        genres = create_genre(admin_client)
        categories = create_categories(admin_client)
        data = {}
        response = admin_client.post('/api/v1/titles/', data=data)
        assert response.status_code == 400, (
            'ѕроверьте, что при POST запросе `/api/v1/titles/` с не правильными данными возвращает статус 400'
        )
        data = {'name': 'ѕоворот туда', 'year': 2000, 'genre': [genres[0]['slug'], genres[1]['slug']],
                'category': categories[0]['slug'], 'description': ' рутое пике'}
>       response = admin_client.post('/api/v1/titles/', data=data)

tests\test_04_title.py:30: 
_ _ _ _ _ _ _ _ _ _ _ _ _ _ _ _ _ _ _ _ _ _ _ _ _ _ _ _ _ _ _ _ _ _ _ _ _ _ _ _
..\venv\lib\site-packages\rest_framework\test.py:296: in post
    path, data=data, format=format, content_type=content_type, **extra)
..\venv\lib\site-packages\rest_framework\test.py:209: in post
    return self.generic('POST', path, data, content_type, **extra)
..\venv\lib\site-packages\rest_framework\test.py:234: in generic
    method, path, data, content_type, secure, **extra)
..\venv\lib\site-packages\django\test\client.py:422: in generic
    return self.request(**r)
..\venv\lib\site-packages\rest_framework\test.py:285: in request
    return super().request(**kwargs)
..\venv\lib\site-packages\rest_framework\test.py:237: in request
    request = super().request(**kwargs)
..\venv\lib\site-packages\django\test\client.py:503: in request
    raise exc_value
..\venv\lib\site-packages\django\core\handlers\exception.py:34: in inner
    response = get_response(request)
..\venv\lib\site-packages\django\core\handlers\base.py:115: in _get_response
    response = self.process_exception_by_middleware(e, request)
..\venv\lib\site-packages\django\core\handlers\base.py:113: in _get_response
    response = wrapped_callback(request, *callback_args, **callback_kwargs)
..\venv\lib\site-packages\django\views\decorators\csrf.py:54: in wrapped_view
    return view_func(*args, **kwargs)
..\venv\lib\site-packages\rest_framework\viewsets.py:125: in view
    return self.dispatch(request, *args, **kwargs)
..\venv\lib\site-packages\rest_framework\views.py:509: in dispatch
    response = self.handle_exception(exc)
..\venv\lib\site-packages\rest_framework\views.py:469: in handle_exception
    self.raise_uncaught_exception(exc)
..\venv\lib\site-packages\rest_framework\views.py:480: in raise_uncaught_exception
    raise exc
..\venv\lib\site-packages\rest_framework\views.py:506: in dispatch
    response = handler(request, *args, **kwargs)
..\venv\lib\site-packages\rest_framework\mixins.py:20: in create
    headers = self.get_success_headers(serializer.data)
..\venv\lib\site-packages\rest_framework\serializers.py:549: in data
    return ReturnDict(ret, serializer=self)
_ _ _ _ _ _ _ _ _ _ _ _ _ _ _ _ _ _ _ _ _ _ _ _ _ _ _ _ _ _ _ _ _ _ _ _ _ _ _ _

self = {}, args = (<Title: ѕоворот туда>,), kwargs = {}

    def __init__(self, *args, **kwargs):
        self.serializer = kwargs.pop('serializer')
>       super().__init__(*args, **kwargs)
E       TypeError: 'Title' object is not iterable

..\venv\lib\site-packages\rest_framework\utils\serializer_helpers.py:18: TypeError
------------------------------ Captured log call ------------------------------
WARNING  django.request:log.py:228 Bad Request: /api/v1/titles/
ERROR    django.request:log.py:228 Internal Server Error: /api/v1/titles/
Traceback (most recent call last):
  File "e:\dev\s_10_project\venv\lib\site-packages\django\core\handlers\exception.py", line 34, in inner
    response = get_response(request)
  File "e:\dev\s_10_project\venv\lib\site-packages\django\core\handlers\base.py", line 115, in _get_response
    response = self.process_exception_by_middleware(e, request)
  File "e:\dev\s_10_project\venv\lib\site-packages\django\core\handlers\base.py", line 113, in _get_response
    response = wrapped_callback(request, *callback_args, **callback_kwargs)
  File "e:\dev\s_10_project\venv\lib\site-packages\django\views\decorators\csrf.py", line 54, in wrapped_view
    return view_func(*args, **kwargs)
  File "e:\dev\s_10_project\venv\lib\site-packages\rest_framework\viewsets.py", line 125, in view
    return self.dispatch(request, *args, **kwargs)
  File "e:\dev\s_10_project\venv\lib\site-packages\rest_framework\views.py", line 509, in dispatch
    response = self.handle_exception(exc)
  File "e:\dev\s_10_project\venv\lib\site-packages\rest_framework\views.py", line 469, in handle_exception
    self.raise_uncaught_exception(exc)
  File "e:\dev\s_10_project\venv\lib\site-packages\rest_framework\views.py", line 480, in raise_uncaught_exception
    raise exc
  File "e:\dev\s_10_project\venv\lib\site-packages\rest_framework\views.py", line 506, in dispatch
    response = handler(request, *args, **kwargs)
  File "e:\dev\s_10_project\venv\lib\site-packages\rest_framework\mixins.py", line 20, in create
    headers = self.get_success_headers(serializer.data)
  File "e:\dev\s_10_project\venv\lib\site-packages\rest_framework\serializers.py", line 549, in data
    return ReturnDict(ret, serializer=self)
  File "e:\dev\s_10_project\venv\lib\site-packages\rest_framework\utils\serializer_helpers.py", line 18, in __init__
    super().__init__(*args, **kwargs)
TypeError: 'Title' object is not iterable
____________________ Test04TitleAPI.test_03_titles_detail _____________________

self = <tests.test_04_title.Test04TitleAPI object at 0x05FFADF0>
client = <django.test.client.Client object at 0x05FFA4B0>
admin_client = <rest_framework.test.APIClient object at 0x05FFA750>

    @pytest.mark.django_db(transaction=True)
    def test_03_titles_detail(self, client, admin_client):
>       titles, categories, genres = create_titles(admin_client)

tests\test_04_title.py:151: 
_ _ _ _ _ _ _ _ _ _ _ _ _ _ _ _ _ _ _ _ _ _ _ _ _ _ _ _ _ _ _ _ _ _ _ _ _ _ _ _
tests\common.py:68: in create_titles
    response = admin_client.post('/api/v1/titles/', data=data)
..\venv\lib\site-packages\rest_framework\test.py:296: in post
    path, data=data, format=format, content_type=content_type, **extra)
..\venv\lib\site-packages\rest_framework\test.py:209: in post
    return self.generic('POST', path, data, content_type, **extra)
..\venv\lib\site-packages\rest_framework\test.py:234: in generic
    method, path, data, content_type, secure, **extra)
..\venv\lib\site-packages\django\test\client.py:422: in generic
    return self.request(**r)
..\venv\lib\site-packages\rest_framework\test.py:285: in request
    return super().request(**kwargs)
..\venv\lib\site-packages\rest_framework\test.py:237: in request
    request = super().request(**kwargs)
..\venv\lib\site-packages\django\test\client.py:503: in request
    raise exc_value
..\venv\lib\site-packages\django\core\handlers\exception.py:34: in inner
    response = get_response(request)
..\venv\lib\site-packages\django\core\handlers\base.py:115: in _get_response
    response = self.process_exception_by_middleware(e, request)
..\venv\lib\site-packages\django\core\handlers\base.py:113: in _get_response
    response = wrapped_callback(request, *callback_args, **callback_kwargs)
..\venv\lib\site-packages\django\views\decorators\csrf.py:54: in wrapped_view
    return view_func(*args, **kwargs)
..\venv\lib\site-packages\rest_framework\viewsets.py:125: in view
    return self.dispatch(request, *args, **kwargs)
..\venv\lib\site-packages\rest_framework\views.py:509: in dispatch
    response = self.handle_exception(exc)
..\venv\lib\site-packages\rest_framework\views.py:469: in handle_exception
    self.raise_uncaught_exception(exc)
..\venv\lib\site-packages\rest_framework\views.py:480: in raise_uncaught_exception
    raise exc
..\venv\lib\site-packages\rest_framework\views.py:506: in dispatch
    response = handler(request, *args, **kwargs)
..\venv\lib\site-packages\rest_framework\mixins.py:20: in create
    headers = self.get_success_headers(serializer.data)
..\venv\lib\site-packages\rest_framework\serializers.py:549: in data
    return ReturnDict(ret, serializer=self)
_ _ _ _ _ _ _ _ _ _ _ _ _ _ _ _ _ _ _ _ _ _ _ _ _ _ _ _ _ _ _ _ _ _ _ _ _ _ _ _

self = {}, args = (<Title: ѕоворот туда>,), kwargs = {}

    def __init__(self, *args, **kwargs):
        self.serializer = kwargs.pop('serializer')
>       super().__init__(*args, **kwargs)
E       TypeError: 'Title' object is not iterable

..\venv\lib\site-packages\rest_framework\utils\serializer_helpers.py:18: TypeError
------------------------------ Captured log call ------------------------------
ERROR    django.request:log.py:228 Internal Server Error: /api/v1/titles/
Traceback (most recent call last):
  File "e:\dev\s_10_project\venv\lib\site-packages\django\core\handlers\exception.py", line 34, in inner
    response = get_response(request)
  File "e:\dev\s_10_project\venv\lib\site-packages\django\core\handlers\base.py", line 115, in _get_response
    response = self.process_exception_by_middleware(e, request)
  File "e:\dev\s_10_project\venv\lib\site-packages\django\core\handlers\base.py", line 113, in _get_response
    response = wrapped_callback(request, *callback_args, **callback_kwargs)
  File "e:\dev\s_10_project\venv\lib\site-packages\django\views\decorators\csrf.py", line 54, in wrapped_view
    return view_func(*args, **kwargs)
  File "e:\dev\s_10_project\venv\lib\site-packages\rest_framework\viewsets.py", line 125, in view
    return self.dispatch(request, *args, **kwargs)
  File "e:\dev\s_10_project\venv\lib\site-packages\rest_framework\views.py", line 509, in dispatch
    response = self.handle_exception(exc)
  File "e:\dev\s_10_project\venv\lib\site-packages\rest_framework\views.py", line 469, in handle_exception
    self.raise_uncaught_exception(exc)
  File "e:\dev\s_10_project\venv\lib\site-packages\rest_framework\views.py", line 480, in raise_uncaught_exception
    raise exc
  File "e:\dev\s_10_project\venv\lib\site-packages\rest_framework\views.py", line 506, in dispatch
    response = handler(request, *args, **kwargs)
  File "e:\dev\s_10_project\venv\lib\site-packages\rest_framework\mixins.py", line 20, in create
    headers = self.get_success_headers(serializer.data)
  File "e:\dev\s_10_project\venv\lib\site-packages\rest_framework\serializers.py", line 549, in data
    return ReturnDict(ret, serializer=self)
  File "e:\dev\s_10_project\venv\lib\site-packages\rest_framework\utils\serializer_helpers.py", line 18, in __init__
    super().__init__(*args, **kwargs)
TypeError: 'Title' object is not iterable
_______________ Test04TitleAPI.test_04_titles_check_permission ________________

self = <tests.test_04_title.Test04TitleAPI object at 0x05A50E30>
client = <django.test.client.Client object at 0x05F0CB90>
admin_client = <rest_framework.test.APIClient object at 0x05F0C5D0>

    @pytest.mark.django_db(transaction=True)
    def test_04_titles_check_permission(self, client, admin_client):
>       titles, categories, genres = create_titles(admin_client)

tests\test_04_title.py:231: 
_ _ _ _ _ _ _ _ _ _ _ _ _ _ _ _ _ _ _ _ _ _ _ _ _ _ _ _ _ _ _ _ _ _ _ _ _ _ _ _
tests\common.py:68: in create_titles
    response = admin_client.post('/api/v1/titles/', data=data)
..\venv\lib\site-packages\rest_framework\test.py:296: in post
    path, data=data, format=format, content_type=content_type, **extra)
..\venv\lib\site-packages\rest_framework\test.py:209: in post
    return self.generic('POST', path, data, content_type, **extra)
..\venv\lib\site-packages\rest_framework\test.py:234: in generic
    method, path, data, content_type, secure, **extra)
..\venv\lib\site-packages\django\test\client.py:422: in generic
    return self.request(**r)
..\venv\lib\site-packages\rest_framework\test.py:285: in request
    return super().request(**kwargs)
..\venv\lib\site-packages\rest_framework\test.py:237: in request
    request = super().request(**kwargs)
..\venv\lib\site-packages\django\test\client.py:503: in request
    raise exc_value
..\venv\lib\site-packages\django\core\handlers\exception.py:34: in inner
    response = get_response(request)
..\venv\lib\site-packages\django\core\handlers\base.py:115: in _get_response
    response = self.process_exception_by_middleware(e, request)
..\venv\lib\site-packages\django\core\handlers\base.py:113: in _get_response
    response = wrapped_callback(request, *callback_args, **callback_kwargs)
..\venv\lib\site-packages\django\views\decorators\csrf.py:54: in wrapped_view
    return view_func(*args, **kwargs)
..\venv\lib\site-packages\rest_framework\viewsets.py:125: in view
    return self.dispatch(request, *args, **kwargs)
..\venv\lib\site-packages\rest_framework\views.py:509: in dispatch
    response = self.handle_exception(exc)
..\venv\lib\site-packages\rest_framework\views.py:469: in handle_exception
    self.raise_uncaught_exception(exc)
..\venv\lib\site-packages\rest_framework\views.py:480: in raise_uncaught_exception
    raise exc
..\venv\lib\site-packages\rest_framework\views.py:506: in dispatch
    response = handler(request, *args, **kwargs)
..\venv\lib\site-packages\rest_framework\mixins.py:20: in create
    headers = self.get_success_headers(serializer.data)
..\venv\lib\site-packages\rest_framework\serializers.py:549: in data
    return ReturnDict(ret, serializer=self)
_ _ _ _ _ _ _ _ _ _ _ _ _ _ _ _ _ _ _ _ _ _ _ _ _ _ _ _ _ _ _ _ _ _ _ _ _ _ _ _

self = {}, args = (<Title: ѕоворот туда>,), kwargs = {}

    def __init__(self, *args, **kwargs):
        self.serializer = kwargs.pop('serializer')
>       super().__init__(*args, **kwargs)
E       TypeError: 'Title' object is not iterable

..\venv\lib\site-packages\rest_framework\utils\serializer_helpers.py:18: TypeError
------------------------------ Captured log call ------------------------------
ERROR    django.request:log.py:228 Internal Server Error: /api/v1/titles/
Traceback (most recent call last):
  File "e:\dev\s_10_project\venv\lib\site-packages\django\core\handlers\exception.py", line 34, in inner
    response = get_response(request)
  File "e:\dev\s_10_project\venv\lib\site-packages\django\core\handlers\base.py", line 115, in _get_response
    response = self.process_exception_by_middleware(e, request)
  File "e:\dev\s_10_project\venv\lib\site-packages\django\core\handlers\base.py", line 113, in _get_response
    response = wrapped_callback(request, *callback_args, **callback_kwargs)
  File "e:\dev\s_10_project\venv\lib\site-packages\django\views\decorators\csrf.py", line 54, in wrapped_view
    return view_func(*args, **kwargs)
  File "e:\dev\s_10_project\venv\lib\site-packages\rest_framework\viewsets.py", line 125, in view
    return self.dispatch(request, *args, **kwargs)
  File "e:\dev\s_10_project\venv\lib\site-packages\rest_framework\views.py", line 509, in dispatch
    response = self.handle_exception(exc)
  File "e:\dev\s_10_project\venv\lib\site-packages\rest_framework\views.py", line 469, in handle_exception
    self.raise_uncaught_exception(exc)
  File "e:\dev\s_10_project\venv\lib\site-packages\rest_framework\views.py", line 480, in raise_uncaught_exception
    raise exc
  File "e:\dev\s_10_project\venv\lib\site-packages\rest_framework\views.py", line 506, in dispatch
    response = handler(request, *args, **kwargs)
  File "e:\dev\s_10_project\venv\lib\site-packages\rest_framework\mixins.py", line 20, in create
    headers = self.get_success_headers(serializer.data)
  File "e:\dev\s_10_project\venv\lib\site-packages\rest_framework\serializers.py", line 549, in data
    return ReturnDict(ret, serializer=self)
  File "e:\dev\s_10_project\venv\lib\site-packages\rest_framework\utils\serializer_helpers.py", line 18, in __init__
    super().__init__(*args, **kwargs)
TypeError: 'Title' object is not iterable
___________________ Test05ReviewAPI.test_01_review_not_auth ___________________

self = <tests.test_05_review.Test05ReviewAPI object at 0x05863710>
client = <django.test.client.Client object at 0x05863C50>
admin_client = <rest_framework.test.APIClient object at 0x05863DF0>

    @pytest.mark.django_db(transaction=True)
    def test_01_review_not_auth(self, client, admin_client):
>       titles, _, _ = create_titles(admin_client)

tests\test_05_review.py:11: 
_ _ _ _ _ _ _ _ _ _ _ _ _ _ _ _ _ _ _ _ _ _ _ _ _ _ _ _ _ _ _ _ _ _ _ _ _ _ _ _
tests\common.py:68: in create_titles
    response = admin_client.post('/api/v1/titles/', data=data)
..\venv\lib\site-packages\rest_framework\test.py:296: in post
    path, data=data, format=format, content_type=content_type, **extra)
..\venv\lib\site-packages\rest_framework\test.py:209: in post
    return self.generic('POST', path, data, content_type, **extra)
..\venv\lib\site-packages\rest_framework\test.py:234: in generic
    method, path, data, content_type, secure, **extra)
..\venv\lib\site-packages\django\test\client.py:422: in generic
    return self.request(**r)
..\venv\lib\site-packages\rest_framework\test.py:285: in request
    return super().request(**kwargs)
..\venv\lib\site-packages\rest_framework\test.py:237: in request
    request = super().request(**kwargs)
..\venv\lib\site-packages\django\test\client.py:503: in request
    raise exc_value
..\venv\lib\site-packages\django\core\handlers\exception.py:34: in inner
    response = get_response(request)
..\venv\lib\site-packages\django\core\handlers\base.py:115: in _get_response
    response = self.process_exception_by_middleware(e, request)
..\venv\lib\site-packages\django\core\handlers\base.py:113: in _get_response
    response = wrapped_callback(request, *callback_args, **callback_kwargs)
..\venv\lib\site-packages\django\views\decorators\csrf.py:54: in wrapped_view
    return view_func(*args, **kwargs)
..\venv\lib\site-packages\rest_framework\viewsets.py:125: in view
    return self.dispatch(request, *args, **kwargs)
..\venv\lib\site-packages\rest_framework\views.py:509: in dispatch
    response = self.handle_exception(exc)
..\venv\lib\site-packages\rest_framework\views.py:469: in handle_exception
    self.raise_uncaught_exception(exc)
..\venv\lib\site-packages\rest_framework\views.py:480: in raise_uncaught_exception
    raise exc
..\venv\lib\site-packages\rest_framework\views.py:506: in dispatch
    response = handler(request, *args, **kwargs)
..\venv\lib\site-packages\rest_framework\mixins.py:20: in create
    headers = self.get_success_headers(serializer.data)
..\venv\lib\site-packages\rest_framework\serializers.py:549: in data
    return ReturnDict(ret, serializer=self)
_ _ _ _ _ _ _ _ _ _ _ _ _ _ _ _ _ _ _ _ _ _ _ _ _ _ _ _ _ _ _ _ _ _ _ _ _ _ _ _

self = {}, args = (<Title: ѕоворот туда>,), kwargs = {}

    def __init__(self, *args, **kwargs):
        self.serializer = kwargs.pop('serializer')
>       super().__init__(*args, **kwargs)
E       TypeError: 'Title' object is not iterable

..\venv\lib\site-packages\rest_framework\utils\serializer_helpers.py:18: TypeError
------------------------------ Captured log call ------------------------------
ERROR    django.request:log.py:228 Internal Server Error: /api/v1/titles/
Traceback (most recent call last):
  File "e:\dev\s_10_project\venv\lib\site-packages\django\core\handlers\exception.py", line 34, in inner
    response = get_response(request)
  File "e:\dev\s_10_project\venv\lib\site-packages\django\core\handlers\base.py", line 115, in _get_response
    response = self.process_exception_by_middleware(e, request)
  File "e:\dev\s_10_project\venv\lib\site-packages\django\core\handlers\base.py", line 113, in _get_response
    response = wrapped_callback(request, *callback_args, **callback_kwargs)
  File "e:\dev\s_10_project\venv\lib\site-packages\django\views\decorators\csrf.py", line 54, in wrapped_view
    return view_func(*args, **kwargs)
  File "e:\dev\s_10_project\venv\lib\site-packages\rest_framework\viewsets.py", line 125, in view
    return self.dispatch(request, *args, **kwargs)
  File "e:\dev\s_10_project\venv\lib\site-packages\rest_framework\views.py", line 509, in dispatch
    response = self.handle_exception(exc)
  File "e:\dev\s_10_project\venv\lib\site-packages\rest_framework\views.py", line 469, in handle_exception
    self.raise_uncaught_exception(exc)
  File "e:\dev\s_10_project\venv\lib\site-packages\rest_framework\views.py", line 480, in raise_uncaught_exception
    raise exc
  File "e:\dev\s_10_project\venv\lib\site-packages\rest_framework\views.py", line 506, in dispatch
    response = handler(request, *args, **kwargs)
  File "e:\dev\s_10_project\venv\lib\site-packages\rest_framework\mixins.py", line 20, in create
    headers = self.get_success_headers(serializer.data)
  File "e:\dev\s_10_project\venv\lib\site-packages\rest_framework\serializers.py", line 549, in data
    return ReturnDict(ret, serializer=self)
  File "e:\dev\s_10_project\venv\lib\site-packages\rest_framework\utils\serializer_helpers.py", line 18, in __init__
    super().__init__(*args, **kwargs)
TypeError: 'Title' object is not iterable
____________________ Test05ReviewAPI.test_02_review_admin _____________________

self = <tests.test_05_review.Test05ReviewAPI object at 0x05B923D0>
admin_client = <rest_framework.test.APIClient object at 0x058C6210>
admin = <User: TestAdmin>

    @pytest.mark.django_db(transaction=True)
    def test_02_review_admin(self, admin_client, admin):
>       titles, _, _ = create_titles(admin_client)

tests\test_05_review.py:32: 
_ _ _ _ _ _ _ _ _ _ _ _ _ _ _ _ _ _ _ _ _ _ _ _ _ _ _ _ _ _ _ _ _ _ _ _ _ _ _ _
tests\common.py:68: in create_titles
    response = admin_client.post('/api/v1/titles/', data=data)
..\venv\lib\site-packages\rest_framework\test.py:296: in post
    path, data=data, format=format, content_type=content_type, **extra)
..\venv\lib\site-packages\rest_framework\test.py:209: in post
    return self.generic('POST', path, data, content_type, **extra)
..\venv\lib\site-packages\rest_framework\test.py:234: in generic
    method, path, data, content_type, secure, **extra)
..\venv\lib\site-packages\django\test\client.py:422: in generic
    return self.request(**r)
..\venv\lib\site-packages\rest_framework\test.py:285: in request
    return super().request(**kwargs)
..\venv\lib\site-packages\rest_framework\test.py:237: in request
    request = super().request(**kwargs)
..\venv\lib\site-packages\django\test\client.py:503: in request
    raise exc_value
..\venv\lib\site-packages\django\core\handlers\exception.py:34: in inner
    response = get_response(request)
..\venv\lib\site-packages\django\core\handlers\base.py:115: in _get_response
    response = self.process_exception_by_middleware(e, request)
..\venv\lib\site-packages\django\core\handlers\base.py:113: in _get_response
    response = wrapped_callback(request, *callback_args, **callback_kwargs)
..\venv\lib\site-packages\django\views\decorators\csrf.py:54: in wrapped_view
    return view_func(*args, **kwargs)
..\venv\lib\site-packages\rest_framework\viewsets.py:125: in view
    return self.dispatch(request, *args, **kwargs)
..\venv\lib\site-packages\rest_framework\views.py:509: in dispatch
    response = self.handle_exception(exc)
..\venv\lib\site-packages\rest_framework\views.py:469: in handle_exception
    self.raise_uncaught_exception(exc)
..\venv\lib\site-packages\rest_framework\views.py:480: in raise_uncaught_exception
    raise exc
..\venv\lib\site-packages\rest_framework\views.py:506: in dispatch
    response = handler(request, *args, **kwargs)
..\venv\lib\site-packages\rest_framework\mixins.py:20: in create
    headers = self.get_success_headers(serializer.data)
..\venv\lib\site-packages\rest_framework\serializers.py:549: in data
    return ReturnDict(ret, serializer=self)
_ _ _ _ _ _ _ _ _ _ _ _ _ _ _ _ _ _ _ _ _ _ _ _ _ _ _ _ _ _ _ _ _ _ _ _ _ _ _ _

self = {}, args = (<Title: ѕоворот туда>,), kwargs = {}

    def __init__(self, *args, **kwargs):
        self.serializer = kwargs.pop('serializer')
>       super().__init__(*args, **kwargs)
E       TypeError: 'Title' object is not iterable

..\venv\lib\site-packages\rest_framework\utils\serializer_helpers.py:18: TypeError
------------------------------ Captured log call ------------------------------
ERROR    django.request:log.py:228 Internal Server Error: /api/v1/titles/
Traceback (most recent call last):
  File "e:\dev\s_10_project\venv\lib\site-packages\django\core\handlers\exception.py", line 34, in inner
    response = get_response(request)
  File "e:\dev\s_10_project\venv\lib\site-packages\django\core\handlers\base.py", line 115, in _get_response
    response = self.process_exception_by_middleware(e, request)
  File "e:\dev\s_10_project\venv\lib\site-packages\django\core\handlers\base.py", line 113, in _get_response
    response = wrapped_callback(request, *callback_args, **callback_kwargs)
  File "e:\dev\s_10_project\venv\lib\site-packages\django\views\decorators\csrf.py", line 54, in wrapped_view
    return view_func(*args, **kwargs)
  File "e:\dev\s_10_project\venv\lib\site-packages\rest_framework\viewsets.py", line 125, in view
    return self.dispatch(request, *args, **kwargs)
  File "e:\dev\s_10_project\venv\lib\site-packages\rest_framework\views.py", line 509, in dispatch
    response = self.handle_exception(exc)
  File "e:\dev\s_10_project\venv\lib\site-packages\rest_framework\views.py", line 469, in handle_exception
    self.raise_uncaught_exception(exc)
  File "e:\dev\s_10_project\venv\lib\site-packages\rest_framework\views.py", line 480, in raise_uncaught_exception
    raise exc
  File "e:\dev\s_10_project\venv\lib\site-packages\rest_framework\views.py", line 506, in dispatch
    response = handler(request, *args, **kwargs)
  File "e:\dev\s_10_project\venv\lib\site-packages\rest_framework\mixins.py", line 20, in create
    headers = self.get_success_headers(serializer.data)
  File "e:\dev\s_10_project\venv\lib\site-packages\rest_framework\serializers.py", line 549, in data
    return ReturnDict(ret, serializer=self)
  File "e:\dev\s_10_project\venv\lib\site-packages\rest_framework\utils\serializer_helpers.py", line 18, in __init__
    super().__init__(*args, **kwargs)
TypeError: 'Title' object is not iterable
____________________ Test05ReviewAPI.test_03_review_detail ____________________

self = <tests.test_05_review.Test05ReviewAPI object at 0x06121BB0>
client = <django.test.client.Client object at 0x05EB9630>
admin_client = <rest_framework.test.APIClient object at 0x05EB9610>
admin = <User: TestAdmin>

    @pytest.mark.django_db(transaction=True)
    def test_03_review_detail(self, client, admin_client, admin):
>       reviews, titles, user, moderator = create_reviews(admin_client, admin)

tests\test_05_review.py:202: 
_ _ _ _ _ _ _ _ _ _ _ _ _ _ _ _ _ _ _ _ _ _ _ _ _ _ _ _ _ _ _ _ _ _ _ _ _ _ _ _
tests\common.py:85: in create_reviews
    titles, _, _ = create_titles(admin_client)
tests\common.py:68: in create_titles
    response = admin_client.post('/api/v1/titles/', data=data)
..\venv\lib\site-packages\rest_framework\test.py:296: in post
    path, data=data, format=format, content_type=content_type, **extra)
..\venv\lib\site-packages\rest_framework\test.py:209: in post
    return self.generic('POST', path, data, content_type, **extra)
..\venv\lib\site-packages\rest_framework\test.py:234: in generic
    method, path, data, content_type, secure, **extra)
..\venv\lib\site-packages\django\test\client.py:422: in generic
    return self.request(**r)
..\venv\lib\site-packages\rest_framework\test.py:285: in request
    return super().request(**kwargs)
..\venv\lib\site-packages\rest_framework\test.py:237: in request
    request = super().request(**kwargs)
..\venv\lib\site-packages\django\test\client.py:503: in request
    raise exc_value
..\venv\lib\site-packages\django\core\handlers\exception.py:34: in inner
    response = get_response(request)
..\venv\lib\site-packages\django\core\handlers\base.py:115: in _get_response
    response = self.process_exception_by_middleware(e, request)
..\venv\lib\site-packages\django\core\handlers\base.py:113: in _get_response
    response = wrapped_callback(request, *callback_args, **callback_kwargs)
..\venv\lib\site-packages\django\views\decorators\csrf.py:54: in wrapped_view
    return view_func(*args, **kwargs)
..\venv\lib\site-packages\rest_framework\viewsets.py:125: in view
    return self.dispatch(request, *args, **kwargs)
..\venv\lib\site-packages\rest_framework\views.py:509: in dispatch
    response = self.handle_exception(exc)
..\venv\lib\site-packages\rest_framework\views.py:469: in handle_exception
    self.raise_uncaught_exception(exc)
..\venv\lib\site-packages\rest_framework\views.py:480: in raise_uncaught_exception
    raise exc
..\venv\lib\site-packages\rest_framework\views.py:506: in dispatch
    response = handler(request, *args, **kwargs)
..\venv\lib\site-packages\rest_framework\mixins.py:20: in create
    headers = self.get_success_headers(serializer.data)
..\venv\lib\site-packages\rest_framework\serializers.py:549: in data
    return ReturnDict(ret, serializer=self)
_ _ _ _ _ _ _ _ _ _ _ _ _ _ _ _ _ _ _ _ _ _ _ _ _ _ _ _ _ _ _ _ _ _ _ _ _ _ _ _

self = {}, args = (<Title: ѕоворот туда>,), kwargs = {}

    def __init__(self, *args, **kwargs):
        self.serializer = kwargs.pop('serializer')
>       super().__init__(*args, **kwargs)
E       TypeError: 'Title' object is not iterable

..\venv\lib\site-packages\rest_framework\utils\serializer_helpers.py:18: TypeError
------------------------------ Captured log call ------------------------------
ERROR    django.request:log.py:228 Internal Server Error: /api/v1/titles/
Traceback (most recent call last):
  File "e:\dev\s_10_project\venv\lib\site-packages\django\core\handlers\exception.py", line 34, in inner
    response = get_response(request)
  File "e:\dev\s_10_project\venv\lib\site-packages\django\core\handlers\base.py", line 115, in _get_response
    response = self.process_exception_by_middleware(e, request)
  File "e:\dev\s_10_project\venv\lib\site-packages\django\core\handlers\base.py", line 113, in _get_response
    response = wrapped_callback(request, *callback_args, **callback_kwargs)
  File "e:\dev\s_10_project\venv\lib\site-packages\django\views\decorators\csrf.py", line 54, in wrapped_view
    return view_func(*args, **kwargs)
  File "e:\dev\s_10_project\venv\lib\site-packages\rest_framework\viewsets.py", line 125, in view
    return self.dispatch(request, *args, **kwargs)
  File "e:\dev\s_10_project\venv\lib\site-packages\rest_framework\views.py", line 509, in dispatch
    response = self.handle_exception(exc)
  File "e:\dev\s_10_project\venv\lib\site-packages\rest_framework\views.py", line 469, in handle_exception
    self.raise_uncaught_exception(exc)
  File "e:\dev\s_10_project\venv\lib\site-packages\rest_framework\views.py", line 480, in raise_uncaught_exception
    raise exc
  File "e:\dev\s_10_project\venv\lib\site-packages\rest_framework\views.py", line 506, in dispatch
    response = handler(request, *args, **kwargs)
  File "e:\dev\s_10_project\venv\lib\site-packages\rest_framework\mixins.py", line 20, in create
    headers = self.get_success_headers(serializer.data)
  File "e:\dev\s_10_project\venv\lib\site-packages\rest_framework\serializers.py", line 549, in data
    return ReturnDict(ret, serializer=self)
  File "e:\dev\s_10_project\venv\lib\site-packages\rest_framework\utils\serializer_helpers.py", line 18, in __init__
    super().__init__(*args, **kwargs)
TypeError: 'Title' object is not iterable
______________ Test05ReviewAPI.test_04_reviews_check_permission _______________

self = <tests.test_05_review.Test05ReviewAPI object at 0x0603CB70>
client = <django.test.client.Client object at 0x0603A950>
admin_client = <rest_framework.test.APIClient object at 0x0603ADB0>
admin = <User: TestAdmin>

    @pytest.mark.django_db(transaction=True)
    def test_04_reviews_check_permission(self, client, admin_client, admin):
>       reviews, titles, user, moderator = create_reviews(admin_client, admin)

tests\test_05_review.py:319: 
_ _ _ _ _ _ _ _ _ _ _ _ _ _ _ _ _ _ _ _ _ _ _ _ _ _ _ _ _ _ _ _ _ _ _ _ _ _ _ _
tests\common.py:85: in create_reviews
    titles, _, _ = create_titles(admin_client)
tests\common.py:68: in create_titles
    response = admin_client.post('/api/v1/titles/', data=data)
..\venv\lib\site-packages\rest_framework\test.py:296: in post
    path, data=data, format=format, content_type=content_type, **extra)
..\venv\lib\site-packages\rest_framework\test.py:209: in post
    return self.generic('POST', path, data, content_type, **extra)
..\venv\lib\site-packages\rest_framework\test.py:234: in generic
    method, path, data, content_type, secure, **extra)
..\venv\lib\site-packages\django\test\client.py:422: in generic
    return self.request(**r)
..\venv\lib\site-packages\rest_framework\test.py:285: in request
    return super().request(**kwargs)
..\venv\lib\site-packages\rest_framework\test.py:237: in request
    request = super().request(**kwargs)
..\venv\lib\site-packages\django\test\client.py:503: in request
    raise exc_value
..\venv\lib\site-packages\django\core\handlers\exception.py:34: in inner
    response = get_response(request)
..\venv\lib\site-packages\django\core\handlers\base.py:115: in _get_response
    response = self.process_exception_by_middleware(e, request)
..\venv\lib\site-packages\django\core\handlers\base.py:113: in _get_response
    response = wrapped_callback(request, *callback_args, **callback_kwargs)
..\venv\lib\site-packages\django\views\decorators\csrf.py:54: in wrapped_view
    return view_func(*args, **kwargs)
..\venv\lib\site-packages\rest_framework\viewsets.py:125: in view
    return self.dispatch(request, *args, **kwargs)
..\venv\lib\site-packages\rest_framework\views.py:509: in dispatch
    response = self.handle_exception(exc)
..\venv\lib\site-packages\rest_framework\views.py:469: in handle_exception
    self.raise_uncaught_exception(exc)
..\venv\lib\site-packages\rest_framework\views.py:480: in raise_uncaught_exception
    raise exc
..\venv\lib\site-packages\rest_framework\views.py:506: in dispatch
    response = handler(request, *args, **kwargs)
..\venv\lib\site-packages\rest_framework\mixins.py:20: in create
    headers = self.get_success_headers(serializer.data)
..\venv\lib\site-packages\rest_framework\serializers.py:549: in data
    return ReturnDict(ret, serializer=self)
_ _ _ _ _ _ _ _ _ _ _ _ _ _ _ _ _ _ _ _ _ _ _ _ _ _ _ _ _ _ _ _ _ _ _ _ _ _ _ _

self = {}, args = (<Title: ѕоворот туда>,), kwargs = {}

    def __init__(self, *args, **kwargs):
        self.serializer = kwargs.pop('serializer')
>       super().__init__(*args, **kwargs)
E       TypeError: 'Title' object is not iterable

..\venv\lib\site-packages\rest_framework\utils\serializer_helpers.py:18: TypeError
------------------------------ Captured log call ------------------------------
ERROR    django.request:log.py:228 Internal Server Error: /api/v1/titles/
Traceback (most recent call last):
  File "e:\dev\s_10_project\venv\lib\site-packages\django\core\handlers\exception.py", line 34, in inner
    response = get_response(request)
  File "e:\dev\s_10_project\venv\lib\site-packages\django\core\handlers\base.py", line 115, in _get_response
    response = self.process_exception_by_middleware(e, request)
  File "e:\dev\s_10_project\venv\lib\site-packages\django\core\handlers\base.py", line 113, in _get_response
    response = wrapped_callback(request, *callback_args, **callback_kwargs)
  File "e:\dev\s_10_project\venv\lib\site-packages\django\views\decorators\csrf.py", line 54, in wrapped_view
    return view_func(*args, **kwargs)
  File "e:\dev\s_10_project\venv\lib\site-packages\rest_framework\viewsets.py", line 125, in view
    return self.dispatch(request, *args, **kwargs)
  File "e:\dev\s_10_project\venv\lib\site-packages\rest_framework\views.py", line 509, in dispatch
    response = self.handle_exception(exc)
  File "e:\dev\s_10_project\venv\lib\site-packages\rest_framework\views.py", line 469, in handle_exception
    self.raise_uncaught_exception(exc)
  File "e:\dev\s_10_project\venv\lib\site-packages\rest_framework\views.py", line 480, in raise_uncaught_exception
    raise exc
  File "e:\dev\s_10_project\venv\lib\site-packages\rest_framework\views.py", line 506, in dispatch
    response = handler(request, *args, **kwargs)
  File "e:\dev\s_10_project\venv\lib\site-packages\rest_framework\mixins.py", line 20, in create
    headers = self.get_success_headers(serializer.data)
  File "e:\dev\s_10_project\venv\lib\site-packages\rest_framework\serializers.py", line 549, in data
    return ReturnDict(ret, serializer=self)
  File "e:\dev\s_10_project\venv\lib\site-packages\rest_framework\utils\serializer_helpers.py", line 18, in __init__
    super().__init__(*args, **kwargs)
TypeError: 'Title' object is not iterable
__________________ Test06CommentAPI.test_01_comment_not_auth __________________

self = <tests.test_06_comment.Test06CommentAPI object at 0x058276B0>
client = <django.test.client.Client object at 0x05FE29B0>
admin_client = <rest_framework.test.APIClient object at 0x05FE2630>
admin = <User: TestAdmin>

    @pytest.mark.django_db(transaction=True)
    def test_01_comment_not_auth(self, client, admin_client, admin):
>       reviews, titles, _, _ = create_reviews(admin_client, admin)

tests\test_06_comment.py:10: 
_ _ _ _ _ _ _ _ _ _ _ _ _ _ _ _ _ _ _ _ _ _ _ _ _ _ _ _ _ _ _ _ _ _ _ _ _ _ _ _
tests\common.py:85: in create_reviews
    titles, _, _ = create_titles(admin_client)
tests\common.py:68: in create_titles
    response = admin_client.post('/api/v1/titles/', data=data)
..\venv\lib\site-packages\rest_framework\test.py:296: in post
    path, data=data, format=format, content_type=content_type, **extra)
..\venv\lib\site-packages\rest_framework\test.py:209: in post
    return self.generic('POST', path, data, content_type, **extra)
..\venv\lib\site-packages\rest_framework\test.py:234: in generic
    method, path, data, content_type, secure, **extra)
..\venv\lib\site-packages\django\test\client.py:422: in generic
    return self.request(**r)
..\venv\lib\site-packages\rest_framework\test.py:285: in request
    return super().request(**kwargs)
..\venv\lib\site-packages\rest_framework\test.py:237: in request
    request = super().request(**kwargs)
..\venv\lib\site-packages\django\test\client.py:503: in request
    raise exc_value
..\venv\lib\site-packages\django\core\handlers\exception.py:34: in inner
    response = get_response(request)
..\venv\lib\site-packages\django\core\handlers\base.py:115: in _get_response
    response = self.process_exception_by_middleware(e, request)
..\venv\lib\site-packages\django\core\handlers\base.py:113: in _get_response
    response = wrapped_callback(request, *callback_args, **callback_kwargs)
..\venv\lib\site-packages\django\views\decorators\csrf.py:54: in wrapped_view
    return view_func(*args, **kwargs)
..\venv\lib\site-packages\rest_framework\viewsets.py:125: in view
    return self.dispatch(request, *args, **kwargs)
..\venv\lib\site-packages\rest_framework\views.py:509: in dispatch
    response = self.handle_exception(exc)
..\venv\lib\site-packages\rest_framework\views.py:469: in handle_exception
    self.raise_uncaught_exception(exc)
..\venv\lib\site-packages\rest_framework\views.py:480: in raise_uncaught_exception
    raise exc
..\venv\lib\site-packages\rest_framework\views.py:506: in dispatch
    response = handler(request, *args, **kwargs)
..\venv\lib\site-packages\rest_framework\mixins.py:20: in create
    headers = self.get_success_headers(serializer.data)
..\venv\lib\site-packages\rest_framework\serializers.py:549: in data
    return ReturnDict(ret, serializer=self)
_ _ _ _ _ _ _ _ _ _ _ _ _ _ _ _ _ _ _ _ _ _ _ _ _ _ _ _ _ _ _ _ _ _ _ _ _ _ _ _

self = {}, args = (<Title: ѕоворот туда>,), kwargs = {}

    def __init__(self, *args, **kwargs):
        self.serializer = kwargs.pop('serializer')
>       super().__init__(*args, **kwargs)
E       TypeError: 'Title' object is not iterable

..\venv\lib\site-packages\rest_framework\utils\serializer_helpers.py:18: TypeError
------------------------------ Captured log call ------------------------------
ERROR    django.request:log.py:228 Internal Server Error: /api/v1/titles/
Traceback (most recent call last):
  File "e:\dev\s_10_project\venv\lib\site-packages\django\core\handlers\exception.py", line 34, in inner
    response = get_response(request)
  File "e:\dev\s_10_project\venv\lib\site-packages\django\core\handlers\base.py", line 115, in _get_response
    response = self.process_exception_by_middleware(e, request)
  File "e:\dev\s_10_project\venv\lib\site-packages\django\core\handlers\base.py", line 113, in _get_response
    response = wrapped_callback(request, *callback_args, **callback_kwargs)
  File "e:\dev\s_10_project\venv\lib\site-packages\django\views\decorators\csrf.py", line 54, in wrapped_view
    return view_func(*args, **kwargs)
  File "e:\dev\s_10_project\venv\lib\site-packages\rest_framework\viewsets.py", line 125, in view
    return self.dispatch(request, *args, **kwargs)
  File "e:\dev\s_10_project\venv\lib\site-packages\rest_framework\views.py", line 509, in dispatch
    response = self.handle_exception(exc)
  File "e:\dev\s_10_project\venv\lib\site-packages\rest_framework\views.py", line 469, in handle_exception
    self.raise_uncaught_exception(exc)
  File "e:\dev\s_10_project\venv\lib\site-packages\rest_framework\views.py", line 480, in raise_uncaught_exception
    raise exc
  File "e:\dev\s_10_project\venv\lib\site-packages\rest_framework\views.py", line 506, in dispatch
    response = handler(request, *args, **kwargs)
  File "e:\dev\s_10_project\venv\lib\site-packages\rest_framework\mixins.py", line 20, in create
    headers = self.get_success_headers(serializer.data)
  File "e:\dev\s_10_project\venv\lib\site-packages\rest_framework\serializers.py", line 549, in data
    return ReturnDict(ret, serializer=self)
  File "e:\dev\s_10_project\venv\lib\site-packages\rest_framework\utils\serializer_helpers.py", line 18, in __init__
    super().__init__(*args, **kwargs)
TypeError: 'Title' object is not iterable
______________________ Test06CommentAPI.test_02_comment _______________________

self = <tests.test_06_comment.Test06CommentAPI object at 0x05996B70>
admin_client = <rest_framework.test.APIClient object at 0x06022F50>
admin = <User: TestAdmin>

    @pytest.mark.django_db(transaction=True)
    def test_02_comment(self, admin_client, admin):
>       reviews, titles, user, moderator = create_reviews(admin_client, admin)

tests\test_06_comment.py:32: 
_ _ _ _ _ _ _ _ _ _ _ _ _ _ _ _ _ _ _ _ _ _ _ _ _ _ _ _ _ _ _ _ _ _ _ _ _ _ _ _
tests\common.py:85: in create_reviews
    titles, _, _ = create_titles(admin_client)
tests\common.py:68: in create_titles
    response = admin_client.post('/api/v1/titles/', data=data)
..\venv\lib\site-packages\rest_framework\test.py:296: in post
    path, data=data, format=format, content_type=content_type, **extra)
..\venv\lib\site-packages\rest_framework\test.py:209: in post
    return self.generic('POST', path, data, content_type, **extra)
..\venv\lib\site-packages\rest_framework\test.py:234: in generic
    method, path, data, content_type, secure, **extra)
..\venv\lib\site-packages\django\test\client.py:422: in generic
    return self.request(**r)
..\venv\lib\site-packages\rest_framework\test.py:285: in request
    return super().request(**kwargs)
..\venv\lib\site-packages\rest_framework\test.py:237: in request
    request = super().request(**kwargs)
..\venv\lib\site-packages\django\test\client.py:503: in request
    raise exc_value
..\venv\lib\site-packages\django\core\handlers\exception.py:34: in inner
    response = get_response(request)
..\venv\lib\site-packages\django\core\handlers\base.py:115: in _get_response
    response = self.process_exception_by_middleware(e, request)
..\venv\lib\site-packages\django\core\handlers\base.py:113: in _get_response
    response = wrapped_callback(request, *callback_args, **callback_kwargs)
..\venv\lib\site-packages\django\views\decorators\csrf.py:54: in wrapped_view
    return view_func(*args, **kwargs)
..\venv\lib\site-packages\rest_framework\viewsets.py:125: in view
    return self.dispatch(request, *args, **kwargs)
..\venv\lib\site-packages\rest_framework\views.py:509: in dispatch
    response = self.handle_exception(exc)
..\venv\lib\site-packages\rest_framework\views.py:469: in handle_exception
    self.raise_uncaught_exception(exc)
..\venv\lib\site-packages\rest_framework\views.py:480: in raise_uncaught_exception
    raise exc
..\venv\lib\site-packages\rest_framework\views.py:506: in dispatch
    response = handler(request, *args, **kwargs)
..\venv\lib\site-packages\rest_framework\mixins.py:20: in create
    headers = self.get_success_headers(serializer.data)
..\venv\lib\site-packages\rest_framework\serializers.py:549: in data
    return ReturnDict(ret, serializer=self)
_ _ _ _ _ _ _ _ _ _ _ _ _ _ _ _ _ _ _ _ _ _ _ _ _ _ _ _ _ _ _ _ _ _ _ _ _ _ _ _

self = {}, args = (<Title: ѕоворот туда>,), kwargs = {}

    def __init__(self, *args, **kwargs):
        self.serializer = kwargs.pop('serializer')
>       super().__init__(*args, **kwargs)
E       TypeError: 'Title' object is not iterable

..\venv\lib\site-packages\rest_framework\utils\serializer_helpers.py:18: TypeError
------------------------------ Captured log call ------------------------------
ERROR    django.request:log.py:228 Internal Server Error: /api/v1/titles/
Traceback (most recent call last):
  File "e:\dev\s_10_project\venv\lib\site-packages\django\core\handlers\exception.py", line 34, in inner
    response = get_response(request)
  File "e:\dev\s_10_project\venv\lib\site-packages\django\core\handlers\base.py", line 115, in _get_response
    response = self.process_exception_by_middleware(e, request)
  File "e:\dev\s_10_project\venv\lib\site-packages\django\core\handlers\base.py", line 113, in _get_response
    response = wrapped_callback(request, *callback_args, **callback_kwargs)
  File "e:\dev\s_10_project\venv\lib\site-packages\django\views\decorators\csrf.py", line 54, in wrapped_view
    return view_func(*args, **kwargs)
  File "e:\dev\s_10_project\venv\lib\site-packages\rest_framework\viewsets.py", line 125, in view
    return self.dispatch(request, *args, **kwargs)
  File "e:\dev\s_10_project\venv\lib\site-packages\rest_framework\views.py", line 509, in dispatch
    response = self.handle_exception(exc)
  File "e:\dev\s_10_project\venv\lib\site-packages\rest_framework\views.py", line 469, in handle_exception
    self.raise_uncaught_exception(exc)
  File "e:\dev\s_10_project\venv\lib\site-packages\rest_framework\views.py", line 480, in raise_uncaught_exception
    raise exc
  File "e:\dev\s_10_project\venv\lib\site-packages\rest_framework\views.py", line 506, in dispatch
    response = handler(request, *args, **kwargs)
  File "e:\dev\s_10_project\venv\lib\site-packages\rest_framework\mixins.py", line 20, in create
    headers = self.get_success_headers(serializer.data)
  File "e:\dev\s_10_project\venv\lib\site-packages\rest_framework\serializers.py", line 549, in data
    return ReturnDict(ret, serializer=self)
  File "e:\dev\s_10_project\venv\lib\site-packages\rest_framework\utils\serializer_helpers.py", line 18, in __init__
    super().__init__(*args, **kwargs)
TypeError: 'Title' object is not iterable
___________________ Test06CommentAPI.test_03_review_detail ____________________

self = <tests.test_06_comment.Test06CommentAPI object at 0x05893B70>
client = <django.test.client.Client object at 0x058E4EB0>
admin_client = <rest_framework.test.APIClient object at 0x058E42B0>
admin = <User: TestAdmin>

    @pytest.mark.django_db(transaction=True)
    def test_03_review_detail(self, client, admin_client, admin):
>       comments, reviews, titles, user, moderator = create_comments(admin_client, admin)

tests\test_06_comment.py:132: 
_ _ _ _ _ _ _ _ _ _ _ _ _ _ _ _ _ _ _ _ _ _ _ _ _ _ _ _ _ _ _ _ _ _ _ _ _ _ _ _
tests\common.py:105: in create_comments
    reviews, titles, user, moderator = create_reviews(admin_client, admin)
tests\common.py:85: in create_reviews
    titles, _, _ = create_titles(admin_client)
tests\common.py:68: in create_titles
    response = admin_client.post('/api/v1/titles/', data=data)
..\venv\lib\site-packages\rest_framework\test.py:296: in post
    path, data=data, format=format, content_type=content_type, **extra)
..\venv\lib\site-packages\rest_framework\test.py:209: in post
    return self.generic('POST', path, data, content_type, **extra)
..\venv\lib\site-packages\rest_framework\test.py:234: in generic
    method, path, data, content_type, secure, **extra)
..\venv\lib\site-packages\django\test\client.py:422: in generic
    return self.request(**r)
..\venv\lib\site-packages\rest_framework\test.py:285: in request
    return super().request(**kwargs)
..\venv\lib\site-packages\rest_framework\test.py:237: in request
    request = super().request(**kwargs)
..\venv\lib\site-packages\django\test\client.py:503: in request
    raise exc_value
..\venv\lib\site-packages\django\core\handlers\exception.py:34: in inner
    response = get_response(request)
..\venv\lib\site-packages\django\core\handlers\base.py:115: in _get_response
    response = self.process_exception_by_middleware(e, request)
..\venv\lib\site-packages\django\core\handlers\base.py:113: in _get_response
    response = wrapped_callback(request, *callback_args, **callback_kwargs)
..\venv\lib\site-packages\django\views\decorators\csrf.py:54: in wrapped_view
    return view_func(*args, **kwargs)
..\venv\lib\site-packages\rest_framework\viewsets.py:125: in view
    return self.dispatch(request, *args, **kwargs)
..\venv\lib\site-packages\rest_framework\views.py:509: in dispatch
    response = self.handle_exception(exc)
..\venv\lib\site-packages\rest_framework\views.py:469: in handle_exception
    self.raise_uncaught_exception(exc)
..\venv\lib\site-packages\rest_framework\views.py:480: in raise_uncaught_exception
    raise exc
..\venv\lib\site-packages\rest_framework\views.py:506: in dispatch
    response = handler(request, *args, **kwargs)
..\venv\lib\site-packages\rest_framework\mixins.py:20: in create
    headers = self.get_success_headers(serializer.data)
..\venv\lib\site-packages\rest_framework\serializers.py:549: in data
    return ReturnDict(ret, serializer=self)
_ _ _ _ _ _ _ _ _ _ _ _ _ _ _ _ _ _ _ _ _ _ _ _ _ _ _ _ _ _ _ _ _ _ _ _ _ _ _ _

self = {}, args = (<Title: ѕоворот туда>,), kwargs = {}

    def __init__(self, *args, **kwargs):
        self.serializer = kwargs.pop('serializer')
>       super().__init__(*args, **kwargs)
E       TypeError: 'Title' object is not iterable

..\venv\lib\site-packages\rest_framework\utils\serializer_helpers.py:18: TypeError
------------------------------ Captured log call ------------------------------
ERROR    django.request:log.py:228 Internal Server Error: /api/v1/titles/
Traceback (most recent call last):
  File "e:\dev\s_10_project\venv\lib\site-packages\django\core\handlers\exception.py", line 34, in inner
    response = get_response(request)
  File "e:\dev\s_10_project\venv\lib\site-packages\django\core\handlers\base.py", line 115, in _get_response
    response = self.process_exception_by_middleware(e, request)
  File "e:\dev\s_10_project\venv\lib\site-packages\django\core\handlers\base.py", line 113, in _get_response
    response = wrapped_callback(request, *callback_args, **callback_kwargs)
  File "e:\dev\s_10_project\venv\lib\site-packages\django\views\decorators\csrf.py", line 54, in wrapped_view
    return view_func(*args, **kwargs)
  File "e:\dev\s_10_project\venv\lib\site-packages\rest_framework\viewsets.py", line 125, in view
    return self.dispatch(request, *args, **kwargs)
  File "e:\dev\s_10_project\venv\lib\site-packages\rest_framework\views.py", line 509, in dispatch
    response = self.handle_exception(exc)
  File "e:\dev\s_10_project\venv\lib\site-packages\rest_framework\views.py", line 469, in handle_exception
    self.raise_uncaught_exception(exc)
  File "e:\dev\s_10_project\venv\lib\site-packages\rest_framework\views.py", line 480, in raise_uncaught_exception
    raise exc
  File "e:\dev\s_10_project\venv\lib\site-packages\rest_framework\views.py", line 506, in dispatch
    response = handler(request, *args, **kwargs)
  File "e:\dev\s_10_project\venv\lib\site-packages\rest_framework\mixins.py", line 20, in create
    headers = self.get_success_headers(serializer.data)
  File "e:\dev\s_10_project\venv\lib\site-packages\rest_framework\serializers.py", line 549, in data
    return ReturnDict(ret, serializer=self)
  File "e:\dev\s_10_project\venv\lib\site-packages\rest_framework\utils\serializer_helpers.py", line 18, in __init__
    super().__init__(*args, **kwargs)
TypeError: 'Title' object is not iterable
______________ Test06CommentAPI.test_04_comment_check_permission ______________

self = <tests.test_06_comment.Test06CommentAPI object at 0x05A08730>
client = <django.test.client.Client object at 0x05FF1030>
admin_client = <rest_framework.test.APIClient object at 0x05FF16F0>
admin = <User: TestAdmin>

    @pytest.mark.django_db(transaction=True)
    def test_04_comment_check_permission(self, client, admin_client, admin):
>       comments, reviews, titles, user, moderator = create_comments(admin_client, admin)

tests\test_06_comment.py:228: 
_ _ _ _ _ _ _ _ _ _ _ _ _ _ _ _ _ _ _ _ _ _ _ _ _ _ _ _ _ _ _ _ _ _ _ _ _ _ _ _
tests\common.py:105: in create_comments
    reviews, titles, user, moderator = create_reviews(admin_client, admin)
tests\common.py:85: in create_reviews
    titles, _, _ = create_titles(admin_client)
tests\common.py:68: in create_titles
    response = admin_client.post('/api/v1/titles/', data=data)
..\venv\lib\site-packages\rest_framework\test.py:296: in post
    path, data=data, format=format, content_type=content_type, **extra)
..\venv\lib\site-packages\rest_framework\test.py:209: in post
    return self.generic('POST', path, data, content_type, **extra)
..\venv\lib\site-packages\rest_framework\test.py:234: in generic
    method, path, data, content_type, secure, **extra)
..\venv\lib\site-packages\django\test\client.py:422: in generic
    return self.request(**r)
..\venv\lib\site-packages\rest_framework\test.py:285: in request
    return super().request(**kwargs)
..\venv\lib\site-packages\rest_framework\test.py:237: in request
    request = super().request(**kwargs)
..\venv\lib\site-packages\django\test\client.py:503: in request
    raise exc_value
..\venv\lib\site-packages\django\core\handlers\exception.py:34: in inner
    response = get_response(request)
..\venv\lib\site-packages\django\core\handlers\base.py:115: in _get_response
    response = self.process_exception_by_middleware(e, request)
..\venv\lib\site-packages\django\core\handlers\base.py:113: in _get_response
    response = wrapped_callback(request, *callback_args, **callback_kwargs)
..\venv\lib\site-packages\django\views\decorators\csrf.py:54: in wrapped_view
    return view_func(*args, **kwargs)
..\venv\lib\site-packages\rest_framework\viewsets.py:125: in view
    return self.dispatch(request, *args, **kwargs)
..\venv\lib\site-packages\rest_framework\views.py:509: in dispatch
    response = self.handle_exception(exc)
..\venv\lib\site-packages\rest_framework\views.py:469: in handle_exception
    self.raise_uncaught_exception(exc)
..\venv\lib\site-packages\rest_framework\views.py:480: in raise_uncaught_exception
    raise exc
..\venv\lib\site-packages\rest_framework\views.py:506: in dispatch
    response = handler(request, *args, **kwargs)
..\venv\lib\site-packages\rest_framework\mixins.py:20: in create
    headers = self.get_success_headers(serializer.data)
..\venv\lib\site-packages\rest_framework\serializers.py:549: in data
    return ReturnDict(ret, serializer=self)
_ _ _ _ _ _ _ _ _ _ _ _ _ _ _ _ _ _ _ _ _ _ _ _ _ _ _ _ _ _ _ _ _ _ _ _ _ _ _ _

self = {}, args = (<Title: ѕоворот туда>,), kwargs = {}

    def __init__(self, *args, **kwargs):
        self.serializer = kwargs.pop('serializer')
>       super().__init__(*args, **kwargs)
E       TypeError: 'Title' object is not iterable

..\venv\lib\site-packages\rest_framework\utils\serializer_helpers.py:18: TypeError
------------------------------ Captured log call ------------------------------
ERROR    django.request:log.py:228 Internal Server Error: /api/v1/titles/
Traceback (most recent call last):
  File "e:\dev\s_10_project\venv\lib\site-packages\django\core\handlers\exception.py", line 34, in inner
    response = get_response(request)
  File "e:\dev\s_10_project\venv\lib\site-packages\django\core\handlers\base.py", line 115, in _get_response
    response = self.process_exception_by_middleware(e, request)
  File "e:\dev\s_10_project\venv\lib\site-packages\django\core\handlers\base.py", line 113, in _get_response
    response = wrapped_callback(request, *callback_args, **callback_kwargs)
  File "e:\dev\s_10_project\venv\lib\site-packages\django\views\decorators\csrf.py", line 54, in wrapped_view
    return view_func(*args, **kwargs)
  File "e:\dev\s_10_project\venv\lib\site-packages\rest_framework\viewsets.py", line 125, in view
    return self.dispatch(request, *args, **kwargs)
  File "e:\dev\s_10_project\venv\lib\site-packages\rest_framework\views.py", line 509, in dispatch
    response = self.handle_exception(exc)
  File "e:\dev\s_10_project\venv\lib\site-packages\rest_framework\views.py", line 469, in handle_exception
    self.raise_uncaught_exception(exc)
  File "e:\dev\s_10_project\venv\lib\site-packages\rest_framework\views.py", line 480, in raise_uncaught_exception
    raise exc
  File "e:\dev\s_10_project\venv\lib\site-packages\rest_framework\views.py", line 506, in dispatch
    response = handler(request, *args, **kwargs)
  File "e:\dev\s_10_project\venv\lib\site-packages\rest_framework\mixins.py", line 20, in create
    headers = self.get_success_headers(serializer.data)
  File "e:\dev\s_10_project\venv\lib\site-packages\rest_framework\serializers.py", line 549, in data
    return ReturnDict(ret, serializer=self)
  File "e:\dev\s_10_project\venv\lib\site-packages\rest_framework\utils\serializer_helpers.py", line 18, in __init__
    super().__init__(*args, **kwargs)
TypeError: 'Title' object is not iterable
-------------------------- Captured stderr teardown ---------------------------
Destroying test database for alias 'default' ('file:memorydb_default?mode=memory&cache=shared')...
============================== warnings summary ===============================
..\venv\lib\site-packages\pkg_resources\_vendor\pyparsing.py:943
  e:\dev\s_10_project\venv\lib\site-packages\pkg_resources\_vendor\pyparsing.py:943: DeprecationWarning: Using or importing the ABCs from 'collections' instead of from 'collections.abc' is deprecated, and in 3.8 it will stop working
    collections.MutableMapping.register(ParseResults)

..\venv\lib\site-packages\pkg_resources\_vendor\pyparsing.py:3226
  e:\dev\s_10_project\venv\lib\site-packages\pkg_resources\_vendor\pyparsing.py:3226: DeprecationWarning: Using or importing the ABCs from 'collections' instead of from 'collections.abc' is deprecated, and in 3.8 it will stop working
    elif isinstance( exprs, collections.Iterable ):

tests/test_00_user_registration.py: 1 warning
tests/test_01_users.py: 12 warnings
tests/test_02_category.py: 13 warnings
tests/test_03_genre.py: 15 warnings
tests/test_04_title.py: 19 warnings
tests/test_05_review.py: 24 warnings
tests/test_06_comment.py: 24 warnings
  e:\dev\s_10_project\venv\lib\site-packages\jwt\api_jwt.py:81: DeprecationWarning: It is strongly recommended that you pass in a value for the "algorithms" argument when calling decode(). This argument will be mandatory in a future version.
    DeprecationWarning

tests/test_00_user_registration.py: 1 warning
tests/test_01_users.py: 12 warnings
tests/test_02_category.py: 13 warnings
tests/test_03_genre.py: 15 warnings
tests/test_04_title.py: 19 warnings
tests/test_05_review.py: 24 warnings
tests/test_06_comment.py: 24 warnings
  e:\dev\s_10_project\venv\lib\site-packages\jwt\api_jws.py:145: DeprecationWarning: It is strongly recommended that you pass in a value for the "algorithms" argument when calling decode(). This argument will be mandatory in a future version.
    DeprecationWarning

tests/test_02_category.py::Test02CategoryAPI::test_01_category_not_auth
tests/test_02_category.py::Test02CategoryAPI::test_02_category_admin
  e:\dev\s_10_project\venv\lib\site-packages\rest_framework\pagination.py:200: UnorderedObjectListWarning: Pagination may yield inconsistent results with an unordered object_list: <class 'reviews.models.Category'> QuerySet.
    paginator = self.django_paginator_class(queryset, page_size)

tests/test_03_genre.py::Test03GenreAPI::test_01_genre_not_auth
tests/test_03_genre.py::Test03GenreAPI::test_02_genre
  e:\dev\s_10_project\venv\lib\site-packages\rest_framework\pagination.py:200: UnorderedObjectListWarning: Pagination may yield inconsistent results with an unordered object_list: <class 'reviews.models.Genre'> QuerySet.
    paginator = self.django_paginator_class(queryset, page_size)

-- Docs: https://docs.pytest.org/en/stable/warnings.html
=========================== short test summary info ===========================
FAILED tests/test_00_user_registration.py::Test00UserRegistration::test_00_valid_data_admin_create_user
FAILED tests/test_00_user_registration.py::Test00UserRegistration::test_00_registration_same_email_restricted
FAILED tests/test_01_users.py::Test01UserAPI::test_01_users_not_authenticated
FAILED tests/test_01_users.py::Test01UserAPI::test_02_users_username_not_authenticated
FAILED tests/test_01_users.py::Test01UserAPI::test_03_users_me_not_authenticated
FAILED tests/test_01_users.py::Test01UserAPI::test_04_users_get_admin - Asser...
FAILED tests/test_01_users.py::Test01UserAPI::test_04_02_users_get_search - A...
FAILED tests/test_01_users.py::Test01UserAPI::test_05_01_users_post_admin - A...
FAILED tests/test_01_users.py::Test01UserAPI::test_06_users_username_get_admin
FAILED tests/test_01_users.py::Test01UserAPI::test_06_users_username_get_not_admin
FAILED tests/test_01_users.py::Test01UserAPI::test_07_01_users_username_patch_admin
FAILED tests/test_01_users.py::Test01UserAPI::test_07_02_users_username_patch_moderator
FAILED tests/test_01_users.py::Test01UserAPI::test_07_03_users_username_patch_user
FAILED tests/test_01_users.py::Test01UserAPI::test_07_05_users_username_put_user_restricted
FAILED tests/test_01_users.py::Test01UserAPI::test_08_01_users_username_delete_admin
FAILED tests/test_01_users.py::Test01UserAPI::test_08_02_users_username_delete_moderator
FAILED tests/test_01_users.py::Test01UserAPI::test_08_03_users_username_delete_user
FAILED tests/test_01_users.py::Test01UserAPI::test_08_04_users_username_delete_superuser
FAILED tests/test_01_users.py::Test01UserAPI::test_09_users_check_permissions
FAILED tests/test_01_users.py::Test01UserAPI::test_10_users_me_get_admin - us...
FAILED tests/test_01_users.py::Test01UserAPI::test_11_01_users_me_patch_admin
FAILED tests/test_01_users.py::Test01UserAPI::test_11_02_users_me_patch_user
FAILED tests/test_02_category.py::Test02CategoryAPI::test_03_category_delete_admin
FAILED tests/test_02_category.py::Test02CategoryAPI::test_04_category_check_permission_admin
FAILED tests/test_02_category.py::Test02CategoryAPI::test_05_category_create_user
FAILED tests/test_02_category.py::Test02CategoryAPI::test_06_category_create_moderator
FAILED tests/test_03_genre.py::Test03GenreAPI::test_03_genres_delete - Assert...
FAILED tests/test_03_genre.py::Test03GenreAPI::test_04_genres_check_permission
FAILED tests/test_03_genre.py::Test03GenreAPI::test_05_genre_create_user - As...
FAILED tests/test_03_genre.py::Test03GenreAPI::test_06_genre_create_moderator
FAILED tests/test_04_title.py::Test04TitleAPI::test_02_title_admin - TypeErro...
FAILED tests/test_04_title.py::Test04TitleAPI::test_03_titles_detail - TypeEr...
FAILED tests/test_04_title.py::Test04TitleAPI::test_04_titles_check_permission
FAILED tests/test_05_review.py::Test05ReviewAPI::test_01_review_not_auth - Ty...
FAILED tests/test_05_review.py::Test05ReviewAPI::test_02_review_admin - TypeE...
FAILED tests/test_05_review.py::Test05ReviewAPI::test_03_review_detail - Type...
FAILED tests/test_05_review.py::Test05ReviewAPI::test_04_reviews_check_permission
FAILED tests/test_06_comment.py::Test06CommentAPI::test_01_comment_not_auth
FAILED tests/test_06_comment.py::Test06CommentAPI::test_02_comment - TypeErro...
FAILED tests/test_06_comment.py::Test06CommentAPI::test_03_review_detail - Ty...
FAILED tests/test_06_comment.py::Test06CommentAPI::test_04_comment_check_permission
================ 41 failed, 12 passed, 222 warnings in 14.69s =================
